Workbook

Sheet Overview
B2: Pokemon Change Docs
B5: These documents will outline all the changes made to the mechanics of the game: including all changes to the stats, typings, abilities, and learnsets of all 649 Pokemon.
B7: Pokemon are grouped together by evolution line, placed in the generation where said line was introduced. For example, Pichu is in Kanto because Pikachu was introduced in Gen 1.
B9: You can find full documentation on moves, abilities, and typing changes on their associated tabs!
B13: Note! | C13: All Pokemon have had their held item chances reduced to 0.
B15: Note! | C15: All Pokemon have had their EV Yields reduced to 0.
B17: Hidden Abilities | C17: Wild Pokemon have a 10% chance to be found with their hidden ability if it's unique from their other abilities.
B21: Move Changes | E21: Ability Changes | H21: Typing Changes
B25: Kanto: #1-151
B28: Johto: #152-251
B31: Hoenn: #252-386
B34: Sinnoh: #387-493
B37: Unova: #494-649

Sheet Kanto
K3: Bulbasaur | M3: Ivysaur | O3: Venusaur | Q3: Now Compatible With
K4: 1 | L4: Tackle | M4: 1 | N4: Tackle | O4: 1 | P4: Spit Up | Q4: TM34: Sludge Wave
K5: 1 | L5: Growl | M5: 1 | N5: Growl | O5: 1 | P5: Petal Dance | Q5: TM57: Weather Ball
K6: 3 | L6: Growth | M6: 3 | N6: Growth | O6: 3 | P6: Growth | Q6: TM85: Play Rough
K7: 5 | L7: Absorb | M7: 5 | N7: Absorb | O7: 5 | P7: Absorb | Q7: TM63: Brutal Swing
K8: 7 | L8: Leech Seed | M8: 7 | N8: Leech Seed | O8: 7 | P8: Leech Seed | Q8: TM54: Breaking Swipe
B9: #1 Bulbasaur | E9: # 2 Ivysaur | H9: #3 Venusaur | K9: 9 | L9: Razor Leaf | M9: 9 | N9: Razor Leaf | O9: 9 | P9: Razor Leaf | Q9: Tutor: Earth Power
A10: Type | B10: Grass | C10: Poison | D10: Type | E10: Grass | F10: Poison | G10: Type | H10: Grass | I10: Poison | K10: 11 | L10: Sweet Scent | M10: 11 | N10: Sweet Scent | O10: 11 | P10: Sweet Scent | Q10: TM05: Knock Off
A11: HP | C11: 45 | D11: HP | F11: 60 | G11: HP | I11: 80 | K11: 13 | L11: Sleep Powder | M11: 13 | N11: Sleep Powder | O11: 13 | P11: Sleep Powder
A12: Attack | C12: 49 | D12: Attack | F12: 62 | G12: Attack | I12: 82 | K12: 13 | L12: Stun Spore | M12: 13 | N12: Stun Spore | O12: 13 | P12: Stun Spore
A13: Defence | C13: 49 | D13: Defence | F13: 63 | G13: Defence | I13: 83 | K13: 15 | L13: Sludge | M13: 15 | N13: Sludge | O13: 15 | P13: Sludge
A14: SpAtk | C14: 65 | D14: SpAtk | F14: 80 | G14: SpAtk | I14: 100 | K14: 19 | L14: Vine Whip | M14: 19 | N14: Vine Whip | O14: 19 | P14: Vine Whip
A15: SpDef | B15: 7+ | C15: 72 | D15: SpDef | E15: 15+ | F15: 95 | G15: SpDef | H15: 20+ | I15: 120 | K15: 21 | L15: Gastro Acid | M15: 21 | N15: Gastro Acid | O15: 21 | P15: Gastro Acid
A16: Speed | C16: 45 | D16: Speed | F16: 60 | G16: Speed | I16: 80 | K16: 24 | L16: Bulldoze | M16: 24 | N16: Bulldoze | O16: 24 | P16: Bulldoze
A17: Total | B17: 15+ | C17: =SUM(C11:C16) -> 325 | D17: Total | E17: 15+ | F17: =SUM(F11:F16) -> 420 | G17: Total | H17: 20+ | I17: =SUM(I11:I16) -> 545 | K17: 27 | L17: Synthesis | M17: 27 | N17: Synthesis | O17: 27 | P17: Synthesis
A18: Ability 1 | B18: Resilient (Shield Dust) | D18: Ability 1 | E18: Resilient (Shield Dust) | G18: Ability 1 | H18: Resilient (Shield Dust) | K18: 32 | L18: Petal Dance | M18: 32 | N18: Petal Dance | O18: 32 | P18: Petal Dance
A19: Ability 2 | B19: Overgrow | D19: Ability 2 | E19: Overgrow | G19: Ability 2 | H19: Overgrow | K19: 36 | L19: Smog | M19: 36 | N19: Smog | O19: 36 | P19: Smog
A20: Ability 3 (HA) | B20: Thick Fat | D20: Ability 3 (HA) | E20: Thick Fat | G20: Ability 3 (HA) | H20: Thick Fat | M20: 40 | N20: Toxic | O20: 40 | P20: Toxic
A21: Evolution Changes | D21: Evolution Changes | G21: Evolution Changes | M21: 43 | N21: Roar | O21: 43 | P21: Roar
M22: 46 | N22: Amnesia | O22: 46 | P22: Amnesia
M23: 50 | N23: Earth Power | O23: 50 | P23: Earth Power
M24: 53 | N24: Sludge Bomb | O24: 53 | P24: Sludge Bomb
O25: 57 | P25: Swords Dance
O26: 62 | P26: Leaf Storm
O27: 70 | P27: Hyper Beam
O28: 78 | P28: Frenzy Plant
K32: Charmander | M32: Charmeleon | O32: Charizard | Q32: Now Compatible With
K33: 1 | L33: Scratch | M33: 1 | N33: Scratch | O33: 1 | P33: Sky Attack | Q33: TM62: Acrobatics
K34: 1 | L34: Growl | M34: 1 | N34: Growl | O34: 1 | P34: Steel Wing | Q34: TM47: Low Sweep
K35: 5 | L35: Ember | M35: 5 | N35: Ember | O35: 1 | P35: Dragon Claw | Q35: TM54: Breaking Swipe
K36: 7 | L36: Smokescreen | M36: 7 | N36: Smokescreen | O36: 7 | P36: Smokescreen | Q36: TM48: Mystical Fire
K37: 10 | L37: Flame Wheel | M37: 10 | N37: Flame Wheel | O37: 10 | P37: Flame Wheel | Q37: TM63: Brutal Swing
B38: #4 Charmander | E38: #5 Charmeleon | H38: #6 Charizard | K38: 13 | L38: Metal Claw | M38: 13 | N38: Metal Claw | O38: 13 | P38: Metal Claw | Q38: Tutor: Dragon Pulse
A39: Type | B39: Fire | D39: Type | E39: Fire | F39: Dragon | G39: Type | H39: Fire | I39: Dragon | K39: 16 | L39: Breaking Swipe | M39: 16 | N39: Breaking Swipe | O39: 16 | P39: Breaking Swipe | Q39: Tutor: Dual Chop
A40: HP | B40: 11+ | C40: 50 | D40: HP | F40: 58 | G40: HP | I40: 78 | K40: 18 | L40: Glare | M40: 18 | N40: Glare | O40: 18 | P40: Glare | Q40: TM18: Scorching Sands
A41: Attack | B41: 15+ | C41: 67 | D41: Attack | E41: 30+ | F41: 89 | G41: Attack | H41: 35+ | I41: 119 | K41: 22 | L41: Slash | M41: 22 | N41: Slash | O41: 22 | P41: Slash | Q41: TM12: Taunt
A42: Defence | C42: 43 | D42: Defence | F42: 58 | G42: Defence | I42: 78 | K42: 25 | L42: Flamethrower | M42: 25 | N42: Flamethrower | O42: 25 | P42: Flamethrower | Q42: Tutor: Draco Meteor
A43: SpAtk | B43: 10- | C43: 50 | D43: SpAtk | E43: 10- | F43: 70 | G43: SpAtk | H43: 29- | I43: 80 | K43: 27 | L43: Scary Face | M43: 27 | N43: Scary Face | O43: 27 | P43: Scary Face
A44: SpDef | C44: 50 | D44: SpDef | F44: 65 | G44: SpDef | I44: 85 | K44: 30 | L44: Thunderpunch | M44: 30 | N44: Thunderpunch | O44: 30 | P44: Thunderpunch
A45: Speed | C45: 65 | D45: Speed | F45: 80 | G45: Speed | H45: 5+ | I45: 105 | K45: 33 | L45: Devour | M45: 33 | N45: Devour | O45: 33 | P45: Devour
...

Sheet New Sheet Idea
B2: Kanto: #1-151 | J2: Note!
J3: Because evolution lines are grouped together, some pokemon from later generations are here.
B4: *note, evolution lines are grouped together, so some gen 2 and 4 mons are here
H9: Bulbasaur | K9: Ivysaur | N9: Venusaur | Q9: Now Compatible With
H10: 1 | J10: Tackle | K10: 1 | M10: Tackle | N10: 1 | P10: Spit Up | Q10: TM34: Sludge Wave
H11: 1 | J11: Growl | K11: 1 | M11: Growl | N11: 1 | P11: Petal Dance | Q11: TM57: Weather Ball
H12: 3 | J12: Growth | K12: 3 | M12: Growth | N12: 3 | P12: Growth | Q12: TM85: Play Rough
H13: 5 | J13: Absorb | K13: 5 | M13: Absorb | N13: 5 | P13: Absorb | Q13: TM63: Brutal Swing
H14: 7 | J14: Leech Seed | K14: 7 | M14: Leech Seed | N14: 7 | P14: Leech Seed | Q14: TM54: Breaking Swipe
B15: #1 Bulbasaur | D15: # 2 Ivysaur | F15: #3 Venusaur | H15: 9 | J15: Razor Leaf | K15: 9 | M15: Razor Leaf | N15: 9 | P15: Razor Leaf | Q15: Tutor: Earth Power
A16: Type | B16: Grass | C16: Poison | D16: Grass | E16: Poison | F16: Grass | G16: Poison | H16: 11 | J16: Sweet Scent | K16: 11 | M16: Sweet Scent | N16: 11 | P16: Sweet Scent | Q16: TM05: Knock Off
A17: HP | C17: 45 | E17: 60 | G17: 80 | H17: 13 | J17: Sleep Powder | K17: 13 | M17: Sleep Powder | N17: 13 | P17: Sleep Powder
A18: Attack | C18: 49 | E18: 62 | G18: 82 | H18: 13 | J18: Stun Spore | K18: 13 | M18: Stun Spore | N18: 13 | P18: Stun Spore
A19: Defence | C19: 49 | E19: 63 | G19: 83 | H19: 15 | J19: Sludge | K19: 15 | M19: Sludge | N19: 15 | P19: Sludge
A20: SpAtk | C20: 65 | E20: 80 | G20: 100 | H20: 19 | J20: Vine Whip | K20: 19 | M20: Vine Whip | N20: 19 | P20: Vine Whip
A21: SpDef | B21: 7+ | C21: 72 | D21: 15+ | E21: 95 | F21: 20+ | G21: 120 | H21: 21 | J21: Gastro Acid | K21: 21 | M21: Gastro Acid | N21: 21 | P21: Gastro Acid
A22: Speed | C22: 45 | E22: 60 | G22: 80 | H22: 24 | J22: Bulldoze | K22: 24 | M22: Bulldoze | N22: 24 | P22: Bulldoze
A23: Total | B23: 15+ | C23: =SUM(C17:C22) -> 325 | D23: 15+ | E23: =SUM(E17:E22) -> 420 | F23: 20+ | G23: =SUM(G17:G22) -> 545 | H23: 27 | J23: Synthesis | K23: 27 | M23: Synthesis | N23: 27 | P23: Synthesis
A24: Ability 1 | B24: Resilient (Shield Dust) | D24: Resilient (Shield Dust) | F24: Resilient (Shield Dust) | H24: 32 | J24: Petal Dance | K24: 32 | M24: Petal Dance | N24: 32 | P24: Petal Dance
A25: Ability 2 | B25: Overgrow | D25: Overgrow | F25: Overgrow | H25: 36 | J25: Smog | K25: 36 | M25: Smog | N25: 36 | P25: Smog
A26: Ability 3 (HA) | B26: Thick Fat | D26: Thick Fat | F26: Thick Fat | K26: 40 | M26: Toxic | N26: 40 | P26: Toxic
A27: Evolution Changes | K27: 43 | M27: Roar | N27: 43 | P27: Roar
K28: 46 | M28: Amnesia | N28: 46 | P28: Amnesia
K29: 50 | M29: Earth Power | N29: 50 | P29: Earth Power
K30: 53 | M30: Sludge Bomb | N30: 53 | P30: Sludge Bomb
N31: 57 | P31: Swords Dance
N32: 62 | P32: Leaf Storm
N33: 70 | P33: Hyper Beam
N34: 78 | P34: Frenzy Plant
H38: Charmander | K38: Charmeleon | N38: Charizard | Q38: Now Compatible With
H39: 1 | J39: Scratch | K39: 1 | M39: Scratch | N39: 1 | P39: Sky Attack | Q39: TM62: Acrobatics
H40: 1 | J40: Growl | K40: 1 | M40: Growl | N40: 1 | P40: Steel Wing | Q40: TM47: Low Sweep
H41: 5 | J41: Ember | K41: 5 | M41: Ember | N41: 1 | P41: Dragon Claw | Q41: TM54: Breaking Swipe
H42: 7 | J42: Smokescreen | K42: 7 | M42: Smokescreen | N42: 7 | P42: Smokescreen | Q42: TM48: Mystical Fire
H43: 10 | J43: Flame Wheel | K43: 10 | M43: Flame Wheel | N43: 10 | P43: Flame Wheel | Q43: TM63: Brutal Swing
B44: #4 Charmander | D44: #5 Charmeleon | F44: #6 Charizard | H44: 13 | J44: Metal Claw | K44: 13 | M44: Metal Claw | N44: 13 | P44: Metal Claw | Q44: Tutor: Dragon Pulse
A45: Type | B45: Fire | D45: Fire | E45: Dragon | F45: Fire | G45: Dragon | H45: 16 | J45: Breaking Swipe | K45: 16 | M45: Breaking Swipe | N45: 16 | P45: Breaking Swipe | Q45: Tutor: Dual Chop
A46: HP | B46: 11+ | C46: 50 | E46: 58 | G46: 78 | H46: 18 | J46: Glare | K46: 18 | M46: Glare | N46: 18 | P46: Glare | Q46: TM18: Scorching Sands
A47: Attack | B47: 15+ | C47: 67 | D47: 30+ | E47: 89 | F47: 35+ | G47: 119 | H47: 22 | J47: Slash | K47: 22 | M47: Slash | N47: 22 | P47: Slash | Q47: TM12: Taunt
A48: Defence | C48: 43 | E48: 58 | G48: 78 | H48: 25 | J48: Flamethrower | K48: 25 | M48: Flamethrower | N48: 25 | P48: Flamethrower | Q48: Tutor: Draco Meteor
...

Sheet Johto
K3: Chikorita | M3: Bayleef | O3: Meganium | Q3: Now Compatible With
K4: 1 | L4: Tackle | M4: 1 | N4: Tackle | O4: 1 | P4: Skull Bash | Q4: TM85: Play Rough
K5: 1 | L5: Growl | M5: 1 | N5: Growl | O5: 1 | P5: Sunny Day | Q5: TM32: Dazzling Gleam
K6: 7 | L6: Poisonpowder | M6: 7 | N6: Poisonpowder | O6: 7 | P6: Poisonpowder | Q6: TM48: Mystical Fire
K7: 10 | L7: Heart Stamp | M7: 10 | N7: Heart Stamp | O7: 10 | P7: Heart Stamp | Q7: TM29: Psychic
K8: 13 | L8: Bullet Seed | M8: 13 | N8: Bullet Seed | O8: 13 | P8: Bullet Seed | Q8: TM79: Body Press
B9: #152 Chikorita | E9: #153 Bayleef | H9: #154 Meganium | K9: 15 | L9: Synthesis | M9: 15 | N9: Synthesis | O9: 15 | P9: Synthesis | Q9: TM92: Solar Blade
A10: Type | B10: Grass | D10: Type | E10: Grass | F10: Fairy | G10: Type | H10: Grass | I10: Fairy | K10: 18 | L10: Take Down | M10: 18 | N10: Take Down | O10: 18 | P10: Take Down | Q10: TM03: Psyshock
A11: HP | C11: 45 | D11: HP | F11: 60 | G11: HP | I11: 80 | K11: 21 | L11: Safeguard | M11: 21 | N11: Safeguard | O11: 21 | P11: Safeguard
A12: Attack | B12: 18+ | C12: 67 | D12: Attack | E12: 25+ | F12: 87 | G12: Attack | H12: 20+ | I12: 102 | K12: 24 | L12: Natural Gift | M12: 24 | N12: Natural Gift | O12: 24 | P12: Natural Gift
A13: Defence | C13: 65 | D13: Defence | F13: 80 | G13: Defence | I13: 100 | K13: 27 | L13: Horn Leech | M13: 27 | N13: Horn Leech | O13: 27 | P13: Horn Leech
A14: SpAtk | B14: 11- | C14: 38 | D14: SpAtk | E14: 10- | F14: 53 | G14: SpAtk | I14: 83 | K14: 30 | L14: Reflect | M14: 30 | N14: Reflect | O14: 30 | P14: Reflect
A15: SpDef | C15: 65 | D15: SpDef | F15: 80 | G15: SpDef | I15: 100 | K15: 30 | L15: Light Screen | M15: 30 | N15: Light Screen | O15: 30 | P15: Light Screen
A16: Speed | C16: 45 | D16: Speed | F16: 60 | G16: Speed | I16: 80 | K16: 33 | L16: Moonblast | M16: 33 | N16: Moonblast | O16: 33 | P16: Moonblast
A17: Total | B17: 7+ | C17: =SUM(C11:C16) -> 325 | D17: Total | E17: 15+ | F17: =SUM(F11:F16) -> 420 | G17: Total | H17: 20+ | I17: =SUM(I11:I16) -> 545 | K17: 38 | L17: Weather Crash | M17: 38 | N17: Weather Crash | O17: 38 | P17: Weather Crash
A18: Ability 1 | B18: Overgrow | D18: Ability 1 | E18: Overgrow | G18: Ability 1 | H18: Overgrow | K18: 41 | L18: Rest | M18: 41 | N18: Rest | O18: 41 | P18: Rest
A19: Ability 2 | B19: Healer | D19: Ability 2 | E19: Healer | G19: Ability 2 | H19: Healer | M19: 46 | N19: Petal Blizzard | O19: 46 | P19: Petal Blizzard
A20: Ability 3 (HA) | B20: Natural Cure | D20: Ability 3 (HA) | E20: Natural Cure | G20: Ability 3 (HA) | H20: Flower Gift | M20: 50 | N20: Earthquake | O20: 50 | P20: Earthquake
A21: Evolution Changes | D21: Evolution Changes | G21: Evolution Changes | M21: 56 | N21: Play Rough | O21: 56 | P21: Play Rough
M22: 60 | N22: Growth | O22: 60 | P22: Growth
M23: 64 | N23: Spirit Break | O23: 64 | P23: Spirit Break
O24: 70 | P24: Giga Impact
O25: 75 | P25: Frenzy Plant
K29: Cyndaquil | M29: Quilava | O29: Typhlosion | Q29: Now Compatible With
K30: 1 | L30: Tackle | M30: 1 | N30: Tackle | O30: 1 | P30: Magma Storm | Q30: Tutor: Earth Power
K31: 1 | L31: Leer | M31: 1 | N31: Leer | O31: 1 | P31: Sand Tomb | Q31: TM48: Mystical Fire
K32: 4 | L32: Smokescreen | M32: 4 | N32: Smokescreen | O32: 4 | P32: Smokescreen
K33: 6 | L33: Ember | M33: 6 | N33: Ember | O33: 6 | P33: Ember
K34: 10 | L34: Quick Attack | M34: 10 | N34: Quick Attack | O34: 10 | P34: Quick Attack
B35: #155 Cyndaquil | E35: #156 Quilava | H35: #157 Typhlosion | K35: 13 | L35: Flame Wheel | M35: 13 | N35: Flame Wheel | O35: 13 | P35: Flame Wheel
A36: Type | B36: Fire | D36: Type | E36: Fire | F36: Ground | G36: Type | H36: Fire | I36: Ground | K36: 17 | L36: Bulldoze | M36: 17 | N36: Bulldoze | O36: 17 | P36: Bulldoze
A37: HP | C37: 39 | D37: HP | F37: 58 | G37: HP | I37: 78 | K37: 20 | L37: Infernal Parade | M37: 20 | N37: Infernal Parade | O37: 20 | P37: Infernal Parade
A38: Attack | C38: 52 | D38: Attack | F38: 64 | G38: Attack | I38: 84 | K38: 24 | L38: Endure | M38: 24 | N38: Endure | O38: 24 | P38: Endure
A39: Defence | C39: 43 | D39: Defence | F39: 58 | G39: Defence | I39: 78 | K39: 27 | L39: Gyro Ball | M39: 27 | N39: Gyro Ball | O39: 27 | P39: Gyro Ball
A40: SpAtk | B40: 16+ | C40: 76 | D40: SpAtk | E40: 15+ | F40: 95 | G40: SpAtk | H40: 11+ | I40: 120 | K40: 30 | L40: Scorching Sands | M40: 30 | N40: Scorching Sands | O40: 30 | P40: Scorching Sands
A41: SpDef | C41: 50 | D41: SpDef | F41: 65 | G41: SpDef | I41: 85 | K41: 33 | L41: Defense Curl | M41: 33 | N41: Defense Curl | O41: 33 | P41: Defense Curl
A42: Speed | C42: 65 | D42: Speed | F42: 80 | G42: Speed | I42: 100 | K42: 36 | L42: Extrasensory | M42: 36 | N42: Extrasensory | O42: 36 | P42: Extrasensory
A43: Total | B43: 11+ | C43: =SUM(C37:C42) -> 325 | D43: Total | E43: 15+ | F43: =SUM(F37:F42) -> 420 | G43: Total | H43: 11+ | I43: =SUM(I37:I42) -> 545 | K43: 40 | L43: Reversal | M43: 40 | N43: Reversal | O43: 40 | P43: Reversal
A44: Ability 1 | B44: Blaze | D44: Ability 1 | E44: Blaze | G44: Ability 1 | H44: Blaze | K44: 44 | L44: Lava Plume | M44: 44 | N44: Lava Plume | O44: 44 | P44: Lava Plume
A45: Ability 2 | B45: Flash Fire | D45: Ability 2 | E45: Flash Fire | G45: Ability 2 | H45: Flash Fire | K45: 48 | L45: Rollout | M45: 48 | N45: Rollout | O45: 48 | P45: Rollout
...

Sheet Kanto - Old
B2: Kanto: #1-151 | I2: Note!
I3: Because evolution lines are grouped together, some pokemon from later generations are here.
B4: *note, evolution lines are grouped together, so some gen 2 and 4 mons are here
H8: Bulbasaur | J8: Ivysaur | L8: Venusaur | N8: Now Compatible With
H9: 1 | I9: Tackle | J9: 1 | K9: Tackle | L9: 1 | M9: Spit Up | N9: TM34: Sludge Wave
H10: 1 | I10: Growth | J10: 1 | K10: Growth | L10: 1 | M10: Petal Dance | N10: TM57: Weather Ball
H11: 7 | I11: Leech Seed | J11: 7 | K11: Leech Seed | L11: 1 | M11: Earth Power | N11: TM85: Play Rough
H12: 9 | I12: Mega Drain | J12: 9 | K12: Mega Drain | L12: 7 | M12: Leech Seed | N12: TM63: Brutal Swing
H13: 13 | I13: Poisonpowder | J13: 13 | K13: Poisonpowder | L13: 9 | M13: Mega Drain | N13: TM54: Breaking Swipe
B14: #1 Bulbasaur | D14: # 2 Ivysaur | F14: #3 Venusaur | H14: 13 | I14: Stun Spore | J14: 13 | K14: Stun Spore | L14: 13 | M14: Poisonpowder | N14: Tutor: Earth Power
A15: Type | B15: Grass | C15: Poison | D15: Grass | E15: Poison | F15: Grass | G15: Poison | H15: 15 | I15: Venoshock | J15: 15 | K15: Venoshock | L15: 13 | M15: Stun Spore | N15: TM05: Knock Off
A16: HP | B16: 2+ | C16: 47 | D16: 10+ | E16: 70 | G16: 80 | H16: 19 | I16: Vine Whip | J16: 19 | K16: Vine Whip | L16: 15 | M16: Venoshock
A17: Attack | C17: 49 | E17: 62 | G17: 82 | H17: 21 | I17: Sweet Scent | J17: 21 | K17: Sweet Scent | L17: 19 | M17: Vine Whip
A18: Defence | C18: 49 | E18: 63 | G18: 83 | H18: 25 | I18: Natural Gift | J18: 25 | K18: Natural Gift | L18: 21 | M18: Sweet Scent
A19: SpAtk | C19: 65 | E19: 80 | F19: 5+ | G19: 105 | H19: 27 | I19: Leaf Tornado | J19: 27 | K19: Leaf Tornado | L19: 25 | M19: Natural Gift
A20: SpDef | B20: 5+ | C20: 70 | D20: 5+ | E20: 85 | F20: 15+ | G20: 115 | H20: 31 | I20: Sludge | J20: 31 | K20: Sludge | L20: 27 | M20: Leaf Tornado
A21: Speed | C21: 45 | E21: 60 | G21: 80 | H21: 33 | I21: Synthesis | J21: 33 | K21: Synthesis | L21: 31 | M21: Sludge
A22: Total | B22: 15+ | C22: =SUM(C16:C21) -> 325 | D22: 15+ | E22: =SUM(E16:E21) -> 420 | F22: 20+ | G22: =SUM(G16:G21) -> 545 | H22: 36 | I22: Giga Drain | J22: 36 | K22: Giga Drain | L22: 33 | M22: Synthesis
A23: Ability 1 | B23: Resilient (Shield Dust) | D23: Resilient (Shield Dust) | F23: Resilient (Shield Dust) | J23: 39 | K23: Amnesia | L23: 36 | M23: Giga Drain
A24: Ability 2 | B24: Overgrow | D24: Overgrow | F24: Overgrow | J24: 44 | K24: Petal Dance | L24: 39 | M24: Amnesia
A25: Ability 3 (HA) | B25: Thick Fat | D25: Thick Fat | F25: Thick Fat | J25: 48 | K25: Solar Beam | L25: 44 | M25: Petal Dance
A26: Evolution Changes | L26: 48 | M26: Solar Beam
L27: 54 | M27: Sludge Bomb
L28: 62 | M28: Toxic
L29: 70 | M29: Leaf Storm
E31: (NEW) | G31: (NEW) | I31: (NEW) | K31: (NEW) | M31: (NEW)
H32: Charmander | J32: Charmeleon | L32: Charizard | N32: Now Compatible With
H33: 1 | I33: Scratch | J33: 1 | K33: Scratch | L33: 1 | M33: Sky Drop | N33: TM62: Acrobatics
H34: 1 | I34: Growl | J34: 1 | K34: Growl | L34: 1 | M34: Steel Wing | N34: TM47: Low Sweep
H35: 4 | I35: Ember | J35: 4 | K35: Ember | L35: 4 | M35: Ember | N35: TM54: Breaking Swipe
H36: 7 | I36: Metal Claw | J36: 7 | K36: Metal Claw | L36: 7 | M36: Metal Claw | N36: TM48: Mystical Fire
H37: 10 | I37: Scary Face | J37: 10 | K37: Scary Face | L37: 10 | M37: Scary Face | N37: TM63: Brutal Swing
B38: #4 Charmander | D38: #5 Charmeleon | F38: #6 Charizard | H38: 13 | I38: Scale Shot | J38: 13 | K38: Scale Shot | L38: 13 | M38: Scale Shot | N38: Tutor: Dragon Pulse
A39: Type | B39: Fire | D39: Fire | E39: Dragon | F39: Fire | G39: Dragon | H39: 16 | I39: Incinerate | J39: 16 | K39: Incinerate | L39: 16 | M39: Incinerate | N39: Tutor: Dual Chop
A40: HP | B40: 11+ | C40: 50 | E40: 58 | G40: 78 | H40: 18 | I40: Taunt | J40: 18 | K40: Taunt | L40: 18 | M40: Taunt | N40: TM18: Scorching Sands
A41: Attack | B41: 15+ | C41: 67 | D41: 30+ | E41: 94 | F41: 36+ | G41: 110 | H41: 21 | I41: Breaking Swipe | J41: 21 | K41: Breaking Swipe | L41: 21 | M41: Breaking Swipe | N41: TM12: Taunt
A42: Defence | C42: 43 | E42: 58 | G42: 78 | H42: 25 | I42: Flamethrower | J42: 25 | K42: Flamethrower | L42: 25 | M42: Flamethrower | N42: Tutor: Draco Meteor
A43: SpAtk | B43: 10- | C43: 50 | D43: 15- | E43: 65 | F43: 15- | G43: 89 | H43: 29 | I43: Slash | J43: 29 | K43: Slash | L43: 29 | M43: Slash
A44: SpDef | C44: 50 | E44: 65 | G44: 85 | H44: 33 | I44: Temper Flare | J44: 33 | K44: Temper Flare | L44: 33 | M44: Temper Flare
A45: Speed | C45: 65 | E45: 80 | F45: 5+ | G45: 105 | H45: 38 | I45: Dual Chop | J45: 38 | K45: Dual Chop | L45: 38 | M45: Dual Chop
...

Sheet Johto (Old)
B2: Johto: #152-251 | I2: Note! | K2: Kanto
I3: Because evolution lines are grouped together, the following Johto pokemon are not on this sheet.
B4: *note, evolution lines are grouped together, so some gen 3 and 4 mons are here
K6: Igglybuff, Cleffa, Pichu, Bellossom, Politoed, Espeon, Umbreon, Slowking, Steelix, Scizor, Kingdra, Porygon2, Tyrogue, Hitmontop, Smoochum, Elekid, Magby, Blissey
I7: (NEW) | K7: (NEW) | M7: (NEW)
H8: Chikorita | J8: Bayleef | L8: Meganium | N8: Now Compatible With
H9: 1 | I9: Tackle | J9: 1 | K9: Tackle | L9: 1 | M9: Skull Bash | N9: TM85: Play Rough
H10: 1 | I10: Growl | J10: 1 | K10: Growl | L10: 1 | M10: Charm | N10: TM32: Dazzling Gleam
H11: 7 | I11: Poisonpowder | J11: 7 | K11: Poisonpowder | L11: 7 | M11: Poisonpowder | N11: TM48: Mystical Fire
H12: 10 | I12: Horn Attack | J12: 10 | K12: Horn Attack | L12: 10 | M12: Horn Attack | N12: TM29: Psychic
H13: 13 | I13: Bullet Seed | J13: 13 | K13: Bullet Seed | L13: 13 | M13: Bullet Seed | N13: TM79: Body Press
B14: #152 Chikorita | D14: #153 Bayleef | F14: #154 Meganium | H14: 15 | I14: Synthesis | J14: 15 | K14: Synthesis | L14: 15 | M14: Synthesis | N14: TM92: Solar Blade
A15: Type | B15: Grass | D15: Grass | E15: Fairy | F15: Grass | G15: Fairy | H15: 18 | I15: Ingrain | J15: 18 | K15: Ingrain | L15: 18 | M15: Ingrain | N15: TM03: Psyshock
A16: HP | B16: 2+ | C16: 47 | D16: 5+ | E16: 65 | F16: 10+ | G16: 90 | H16: 21 | I16: Doubleslap | J16: 21 | K16: Doubleslap | L16: 21 | M16: Doubleslap
A17: Attack | B17: 10+ | C17: 59 | D17: 20+ | E17: 82 | F17: 25+ | G17: 107 | H17: 24 | I17: Natural Gift | J17: 24 | K17: Natural Gift | L17: 24 | M17: Natural Gift
A18: Defence | C18: 65 | E18: 80 | G18: 100 | H18: 27 | I18: Vine Whip | J18: 27 | K18: Vine Whip | L18: 27 | M18: Vine Whip
A19: SpAtk | B19: 10- | C19: 39 | D19: 10- | E19: 53 | F19: 15- | G19: 68 | H19: 30 | I19: Reflect | J19: 30 | K19: Reflect | L19: 30 | M19: Reflect
A20: SpDef | C20: 65 | E20: 80 | G20: 100 | H20: 30 | I20: Light Screen | J20: 30 | K20: Light Screen | L20: 30 | M20: Light Screen
A21: Speed | B21: 5+ | C21: 50 | E21: 60 | G21: 80 | H21: 33 | I21: Take Down | J21: 33 | K21: Take Down | L21: 33 | M21: Take Down
A22: Total | B22: 7+ | C22: =SUM(C16:C21) -> 325 | D22: 15+ | E22: =SUM(E16:E21) -> 420 | F22: 20+ | G22: =SUM(G16:G21) -> 545 | H22: 38 | I22: Play Rough | J22: 38 | K22: Play Rough | L22: 38 | M22: Play Rough
A23: Ability 1 | B23: Overgrow | D23: Overgrow | F23: Overgrow | H23: 41 | I23: Petal Blizzard | J23: 41 | K23: Petal Blizzard | L23: 41 | M23: Petal Blizzard
A24: Ability 2 | B24: Pixilate | D24: Healer | F24: Healer | J24: 46 | K24: Rest | L24: 46 | M24: Rest
A25: Ability 3 (HA) | B25: Natural Cure | D25: Natural Cure | F25: Flower Gift | J25: 50 | K25: Earthquake | L25: 50 | M25: Earthquake
A26: Evolution Changes | J26: 56 | K26: Swords Dance | L26: 56 | M26: Swords Dance
J27: 60 | K27: Facade | L27: 60 | M27: Facade
J28: 64 | K28: Spirit Break | L28: 64 | M28: Spirit Break
L29: 70 | M29: Giga Impact
L30: 75 | M30: Frenzy Plant
C32: (NEW) | E32: (NEW) | G32: (NEW) | I32: (NEW) | K32: (NEW) | M32: (NEW)
H33: Cyndaquil | J33: Quilava | L33: Typhlosion | N33: Now Compatible With
H34: 1 | I34: Tackle | J34: 1 | K34: Tackle | L34: 1 | M34: Magma Storm | N34: Tutor: Earth Power
H35: 1 | I35: Leer | J35: 1 | K35: Leer | L35: 1 | M35: Sand Tomb | N35: TM48: Mystical Fire
H36: 4 | I36: Smokescreen | J36: 4 | K36: Smokescreen | L36: 4 | M36: Smokescreen
H37: 6 | I37: Ember | J37: 6 | K37: Ember | L37: 6 | M37: Ember
H38: 10 | I38: Quick Attack | J38: 10 | K38: Quick Attack | L38: 10 | M38: Quick Attack
B39: #155 Cyndaquil | D39: #156 Quilava | F39: #157 Typhlosion | H39: 13 | I39: Flame Wheel | J39: 13 | K39: Flame Wheel | L39: 13 | M39: Flame Wheel
A40: Type | B40: Fire | D40: Fire | E40: Ground | F40: Fire | G40: Ground | H40: 17 | I40: Mud Shot | J40: 17 | K40: Mud Shot | L40: 17 | M40: Mud Shot
A41: HP | B41: 11+ | C41: 50 | D41: 8+ | E41: 66 | G41: 78 | H41: 20 | I41: Infernal Parade | J41: 20 | K41: Infernal Parade | L41: 20 | M41: Infernal Parade
A42: Attack | C42: 52 | E42: 64 | G42: 84 | H42: 24 | I42: Reversal | J42: 24 | K42: Reversal | L42: 24 | M42: Reversal
A43: Defence | C43: 43 | D43: 7+ | E43: 65 | G43: 78 | H43: 27 | I43: Facade | J43: 27 | K43: Facade | L43: 27 | M43: Facade
...

Sheet Hoenn
K2: Treecko | M2: Grovyle | O2: Sceptile | Q2: Now Compatible With
K3: 1 | L3: Tackle | M3: 1 | N3: Tackle | O3: 1 | P3: Fake Out | Q3: TM89: U-turn
K4: 1 | L4: Absorb | M4: 1 | N4: Absorb | O4: 1 | P4: Growth | Q4: Tutor Draco Meteor
K5: 1 | L5: Leer | M5: 1 | N5: Leer | O5: 1 | P5: Leer
K6: 1 | L6: Quick Attack | M6: 1 | N6: Quick Attack | O6: 1 | P6: Quick Attack
K7: 5 | L7: Mega Drain | M7: 5 | N7: Mega Drain | O7: 5 | P7: Mega Drain
B8: #252 Treecko | E8: #253 Grovyle | H8: #254 Sceptile | K8: 9 | L8: Pursuit | M8: 9 | N8: Pursuit | O8: 9 | P8: Pursuit
A9: Type | B9: Grass | D9: Type | E9: Grass | F9: Dragon | G9: Type | H9: Grass | I9: Dragon | K9: 13 | L9: Double Team | M9: 13 | N9: Double Team | O9: 13 | P9: Double Team
A10: HP | C10: 40 | D10: HP | F10: 50 | G10: HP | I10: 70 | K10: 16 | L10: Breaking Swipe | M10: 16 | N10: Breaking Swipe | O10: 16 | P10: Breaking Swipe
A11: Attack | B11: 15+ | C11: 60 | D11: Attack | E11: 20+ | F11: 85 | G11: Attack | H11: 15+ | I11: 100 | K11: 19 | L11: Trop Kick | M11: 19 | N11: Trop Kick | O11: 19 | P11: Trop Kick
A12: Defence | C12: 35 | D12: Defence | F12: 45 | G12: Defence | I12: 65 | K12: 22 | L12: Night Slash | M12: 22 | N12: Night Slash | O12: 22 | P12: Night Slash
A13: SpAtk | C13: 65 | D13: SpAtk | F13: 85 | G13: SpAtk | I13: 105 | K13: 25 | L13: Screech | M13: 25 | N13: Screech | O13: 25 | P13: Screech
A14: SpDef | C14: 50 | D14: SpDef | F14: 60 | G14: SpDef | I14: 85 | K14: 29 | L14: Dragon Breath | M14: 29 | N14: Dragon Breath | O14: 29 | P14: Dragon Breath
A15: Speed | C15: 70 | D15: Speed | E15: ````````````````````````````````````````````````````````````````````````````````````````````````````````````````````````````````````````````````````````````````````````````````````````````````````````````````````````````````````````````````````````````````````````````````````````````````````````````````````````````````````````````````````````````````````````````````````````````````````````````````````````````````````````````````````````````````````````````````````````````````````````````````````````````````````````````````````````````````````````````````````````````````````````````````````````````````````````````````````````````````````````````````````````````````````````````````````````````````````````````````````````````````````````````````````````````````````````````````````````````````````````````````````````````````````````````````````````````````````````````````````````````````````````````````````````````````````````````````````````````````````````````````````````````````````````````````````````````````````````````````````````````````````````````````````````````````````````````````````````````````````````````````````````````````````````````````````````````````````````````````````````````````````````````````````````````````````````````````````````````````````````````````````````````````````````````````````````````````````````````````````````````````````````````````````````````````````````````````````````````````````````````````````````````````````````````````````````````````````````````````````````````````````````````````````````````````````````````````````````````````````````````````````````````````````````````````````````````````````````````````````````````````````````````````````````````````````````````````````````````````````````````````````````````````````````````````````````````````````````````````````````````````````````````````````````````````````````````````````````````````````````````````````````````````````````````````````````````````````````````````````````````````````````````````````````````````````````````````````````````````````````````````````````````````````````````````````````````````````````````````````````````````````````````````````````````````````````````````````````````````````````````````````````````````````````````````````````````````````````````````````````````````````````````````````````````````````````````````````````````````````````````````````````````````````````````````````````````````````````````````````````````````````````````````````````````````````````````````````````````````````````````````````````````````````````````````````````````````````````````````````````````````````````````````````````````````````````````````````````````````````````````````````````````````````````````````````````````````````````````````````````````````````````````````````````````````````````````````````````````````````````````````````````````````````````````````````````````````````````````````````````````````````````````````````````````````````````````````````````````````````````````````````````````````````````````````````````````````````````````````````````````````````````````````````````````````````````````````````````````````````````````````````````````````````````````````````````````````````````````````````````````````````````````````````````````````````````````````````````````````````````````````````````````````````````````````````````````````````````````````````````````````````````````````````````````````````````````````````````````````````````````````````````````````````````````````````````````````````````````````````````````````````````````````````````````````````````````````````````````````````````````````````````````````````````````````````````````````````````````````````````````````````````````````````````````````````````````````````````````````````````````````````````````````````````````````````````````````````````````````````````````````````````````````````````````````````````````````````````````````````````````````````````````````````````````````````````````````````````````````````````````````````````````````````````````````````````````````````````````````````````````````````````````````````````````````````````````````````````````````````````````````````````````````````````````````````````````````````````````````````````````````````````````````````````````````````````````````````````````````````````````````````````````````````````````````````````````````````````````````````````````````````````````````````````````````````````````````````````````````````````````````````````````````````````````````````````````````````````````````````````````````````````````````````````````````````````````````````````````````````````````````````````````````````````````````````````````````````````````````````````````````````````````````````````````````````````````````````````````````````````````````````````````````````````````````````````````````````````````````````````````````````````````````````````````````````````````````````````````````````````````````````````````````````````````````````````````````````````````````````````````````````````````````````````````````````````````````````````````````````````````````````````````````````````````````````````````````````````````````````````````````````````````````````````````````````````````````````````````````````````````````````````````````````````````````````````````````````````````````````````````````````````````````````````````````````````````````````````````````````````````````````````````````````````````````````````````````````````````````````````````````````````````````````````````````````````````````````````````````````````````````````````````````````````````````````````````````````````````````````````````````````````````````````````````````````````````````````````````````````````````````````````````````````````````````````````5` | F15: 95 | G15: Speed | I15: 120 | K15: 33 | L15: Air Cutter | M15: 33 | N15: Air Cutter | O15: 33 | P15: Air Cutter
A16: Total | B16: 15+ | C16: =SUM(C10:C15) -> 320 | D16: Total | E16: 20+ | F16: =SUM(F10:F15) -> 420 | G16: Total | H16: 15+ | I16: =SUM(I10:I15) -> 545 | K16: 36 | L16: Leaf Blade | M16: 36 | N16: Leaf Blade | O16: 36 | P16: Leaf Blade
A17: Ability 1 | B17: Overgrow | D17: Ability 1 | E17: Hyper Cutter | G17: Ability 1 | H17: Hyper Cutter | K17: 40 | L17: Synthesis | M17: 40 | N17: Synthesis | O17: 40 | P17: Synthesis
A18: Ability 2 | B18: Unburden | D18: Ability 2 | E18: Unburden | G18: Ability 2 | H18: Unburden | K18: 43 | L18: Dual Chop | M18: 43 | N18: Dual Chop | O18: 43 | P18: Dual Chop
A19: Ability 3 (HA) | B19: Technician | D19: Ability 3 (HA) | E19: Technician | G19: Ability 3 (HA) | H19: Exploit (Download) | K19: 47 | L19: Air Slash | M19: 47 | N19: Air Slash | O19: 47 | P19: Air Slash
A20: Evolution Changes | D20: Evolution Changes | G20: Evolution Changes | M20: 54 | N20: U-Turn | O20: 54 | P20: U-Turn
M21: 60 | N21: Detect | O21: 60 | P21: Detect
O22: 64 | P22: Outrage
O23: 68 | P23: Leaf Storm
O24: 75 | P24: Frenzy Plant
O25: 99 | P25: Draco Meteor
K29: Torchic | M29: Combusken | O29: Blaziken | Q29: Now Compatible With
K30: 1 | L30: Scratch | M30: 1 | N30: Scratch | O30: 1 | P30: Scratch | Q30: TM89: U-turn
K31: 1 | L31: Growl | M31: 1 | N31: Growl | O31: 1 | P31: Growl | Q31: TM18: Scorching Sands
K32: 4 | L32: Peck | M32: 4 | N32: Peck | O32: 4 | P32: Peck | Q32: TM07: Drain Punch
K33: 7 | L33: Sand Attack | M33: 7 | N33: Sand Attack | O33: 7 | P33: Sand Attack | Q33: HM02: Fly
K34: 10 | L34: Quick Attack | M34: 10 | N34: Quick Attack | O34: 10 | P34: Quick Attack | Q34: TM58: Hurricane
B35: #255 Torchic | E35: #256 Combusken | H35: #257 Blaziken | K35: 13 | L35: Pluck | M35: 13 | N35: Pluck | O35: 13 | P35: Pluck | Q35: TM11: Air Slash
A36: Type | B36: Fire | D36: Type | E36: Fire | F36: Flying | G36: Type | H36: Fire | I36: Flying | K36: 16 | L36: Double Kick | M36: 16 | N36: Double Kick | O36: 16 | P36: Double Kick | Q36: TM62: Acrobatics
A37: HP | C37: 45 | D37: HP | F37: 60 | G37: HP | I37: 80 | K37: 19 | L37: Flame Burst | M37: 19 | N37: Flame Burst | O37: 19 | P37: Flame Burst | Q37: TM46: Aura Sphere
A38: Attack | C38: 60 | D38: Attack | F38: 85 | G38: Attack | I38: 120 | K38: 22 | L38: Endure | M38: 22 | N38: Endure | O38: 22 | P38: Endure
A39: Defence | C39: 40 | D39: Defence | F39: 60 | G39: Defence | I39: 70 | K39: 25 | L39: U-turn | M39: 25 | N39: U-turn | O39: 25 | P39: U-turn
A40: SpAtk | C40: 70 | D40: SpAtk | F40: 85 | G40: SpAtk | I40: 110 | K40: 28 | L40: Sky Uppercut | M40: 28 | N40: Sky Uppercut | O40: 28 | P40: Sky Uppercut
A41: SpDef | C41: 50 | D41: SpDef | F41: 60 | G41: SpDef | I41: 70 | K41: 31 | L41: Bounce | M41: 31 | N41: Bounce | O41: 31 | P41: Bounce
A42: Speed | B42: 15+ | C42: 60 | D42: Speed | E42: 15+ | F42: 70 | G42: Speed | H42: 15+ | I42: 95 | K42: 34 | L42: Reversal | M42: 34 | N42: Reversal | O42: 34 | P42: Reversal
A43: Total | B43: 15+ | C43: =SUM(C37:C42) -> 325 | D43: Total | E43: 15+ | F43: =SUM(F37:F42) -> 420 | G43: Total | H43: 15+ | I43: =SUM(I37:I42) -> 545 | K43: 40 | L43: Blaze Kick | M43: 40 | N43: Blaze Kick | O43: 40 | P43: Blaze Kick
A44: Ability 1 | B44: Blaze | D44: Ability 1 | E44: Blaze | G44: Ability 1 | H44: Blaze | K44: 44 | L44: Feather Dance | M44: 44 | N44: Feather Dance | O44: 44 | P44: Feather Dance
...

Sheet Sinnoh
K3: Turtwig | M3: Grotle | O3: Torterra | Q3: Now Compatible With
K4: 1 | L4: Tackle | M4: 1 | N4: Tackle | O4: 1 | P4: Giga Impact | Q4: TM68: Avalanche
K5: 1 | L5: Harden | M5: 1 | N5: Harden | O5: 1 | P5: Fissure | Q5: TM01: Psychic Fangs
K6: 1 | L6: Absorb | M6: 1 | N6: Absorb | O6: 1 | P6: Ingrain
K7: 1 | L7: Mud Slap | M7: 1 | N7: Mud Slap | O7: 1 | P7: Skull Bash
K8: 7 | L8: Razor Leaf | M8: 7 | N8: Razor Leaf | O8: 7 | P8: Razor Leaf
B9: #387 Turtwig | E9: #388 Grotle | H9: #389 Torterra | K9: 10 | L9: Stomp | M9: 10 | N9: Stomp | O9: 10 | P9: Stomp
A10: Type | B10: Grass | D10: Type | E10: Grass | F10: Ground | G10: Type | H10: Grass | I10: Ground | K10: 13 | L10: Bite | M10: 13 | N10: Bite | O10: 13 | P10: Bite
A11: HP | C11: 55 | D11: HP | F11: 75 | G11: HP | I11: 95 | K11: 16 | L11: Leech Seed | M11: 16 | N11: Leech Seed | O11: 16 | P11: Leech Seed
A12: Attack | C12: 68 | D12: Attack | F12: 89 | G12: Attack | I12: 109 | K12: 19 | L12: Bulldoze | M12: 19 | N12: Bulldoze | O12: 19 | P12: Bulldoze
A13: Defence | B13: 2+ | C13: 66 | D13: Defence | E13: 15+ | F13: 100 | G13: Defence | H13: 20+ | I13: 125 | K13: 22 | L13: Razor Shell | M13: 22 | N13: Razor Shell | O13: 22 | P13: Razor Shell
A14: SpAtk | C14: 45 | D14: SpAtk | F14: 55 | G14: SpAtk | I14: 75 | K14: 25 | L14: Crunch | M14: 25 | N14: Crunch | O14: 25 | P14: Crunch
A15: SpDef | C15: 55 | D15: SpDef | F15: 65 | G15: SpDef | I15: 85 | K15: 29 | L15: Seed Bomb | M15: 29 | N15: Seed Bomb | O15: 29 | P15: Seed Bomb
A16: Speed | C16: 36 | D16: Speed | F16: 36 | G16: Speed | I16: 56 | K16: 32 | L16: Wide Guard | M16: 32 | N16: Wide Guard | O16: 32 | P16: Wide Guard
A17: Total | B17: 2+ | C17: =SUM(C11:C16) -> 325 | D17: Total | E17: 15+ | F17: =SUM(F11:F16) -> 420 | G17: Total | H17: 20+ | I17: =SUM(I11:I16) -> 545 | K17: 36 | L17: Stompin Tantrum | M17: 36 | N17: Stompin Tantrum | O17: 36 | P17: Stompin Tantrum
A18: Ability 1 | B18: Shell Armor | D18: Ability 1 | E18: Shell Armor | G18: Ability 1 | H18: Shell Armor | K18: 40 | L18: Synthesis | M18: 40 | N18: Synthesis | O18: 40 | P18: Synthesis
A19: Ability 2 | B19: Overgrow | D19: Ability 2 | E19: Overgrow | G19: Ability 2 | H19: Determined (Rock Head) | M19: 44 | N19: Leaf Storm | O19: 44 | P19: Leaf Storm
A20: Ability 3 (HA) | B20: Solid Rock | D20: Ability 3 (HA) | E20: Solid Rock | G20: Ability 3 (HA) | H20: Solid Rock | M20: 46 | N20: Rock Polish | O20: 46 | P20: Rock Polish
A21: Evolution Changes | D21: Evolution Changes | G21: Evolution Changes | M21: 49 | N21: Rock Wrecker | O21: 49 | P21: Rock Wrecker
O22: 55 | P22: Earthquake
O23: 61 | P23: Wood Hammer
O24: 66 | P24: Curse
O25: 70 | P25: Headlong Rush
O26: 75 | P26: Frenzy Plant
K30: Chimchar | M30: Monferno | O30: Infernape | Q30: Now Compatible With
K31: 1 | L31: Scratch | M31: 1 | N31: Scratch | O31: 1 | P31: Focus Energy | Q31: TM05: Knock Off
K32: 1 | L32: Leer | M32: 1 | N32: Leer | O32: 1 | P32: Fake Out | Q32: TM07: Drain Punch
K33: 1 | L33: Ember | M33: 1 | N33: Ember | O33: 1 | P33: Ember
K34: 8 | L34: Covet | M34: 8 | N34: Covet | O34: 8 | P34: Covet
K35: 10 | L35: Flame Wheel | M35: 10 | N35: Flame Wheel | O35: 10 | P35: Flame Wheel
B36: #390 Chimchar | E36: #391 Monferno | H36: #392 Infernape | K36: 14 | L36: Mach Punch | M36: 14 | N36: Mach Punch | O36: 14 | P36: Mach Punch
A37: Type | B37: Fire | D37: Type | E37: Fire | F37: Fighting | G37: Type | H37: Fire | I37: Fighting | K37: 17 | L37: Counter | M37: 17 | N37: Counter | O37: 17 | P37: Counter
A38: HP | C38: 44 | D38: HP | F38: 64 | G38: HP | I38: 76 | K38: 20 | L38: Force Palm | M38: 20 | N38: Force Palm | O38: 20 | P38: Force Palm
A39: Attack | C39: 61 | D39: Attack | F39: 85 | G39: Attack | I39: 104 | K39: 23 | L39: Screech | M39: 23 | N39: Screech | O39: 23 | P39: Screech
A40: Defence | C40: 44 | D40: Defence | F40: 52 | G40: Defence | I40: 71 | K40: 27 | L40: Torment | M40: 27 | N40: Torment | O40: 27 | P40: Torment
A41: SpAtk | C41: 61 | D41: SpAtk | F41: 85 | G41: SpAtk | I41: 104 | K41: 30 | L41: Temper Flare | M41: 30 | N41: Temper Flare | O41: 30 | P41: Temper Flare
A42: SpDef | C42: 44 | D42: SpDef | F42: 52 | G42: SpDef | I42: 71 | K42: 33 | L42: Taunt | M42: 33 | N42: Taunt | O42: 33 | P42: Taunt
A43: Speed | B43: 16+ | C43: 77 | D43: Speed | E43: 15+ | F43: 96 | G43: Speed | H43: 11+ | I43: 119 | K43: 36 | L43: Sky Uppercut | M43: 36 | N43: Sky Uppercut | O43: 36 | P43: Sky Uppercut
A44: Total | B44: 16+ | C44: =SUM(C38:C43) -> 331 | D44: Total | E44: 15+ | F44: =SUM(F38:F43) -> 434 | G44: Total | H44: 11+ | I44: =SUM(I38:I43) -> 545 | K44: 39 | L44: Thunder Punch | M44: 39 | N44: Thunder Punch | O44: 39 | P44: Thunder Punch
A45: Ability 1 | B45: Iron Fist | D45: Ability 1 | E45: Iron Fist | G45: Ability 1 | H45: Iron Fist | K45: 41 | L45: Switcheroo | M45: 41 | N45: Switcheroo | O45: 41 | P45: Switcheroo
...

Sheet TestDrive-Included TMs and Move
B2: Unova: #494-649
H6: Victini | N6: Now Compatible With | S6: Move Tutor
H7: 1 | I7: Searing Shot | N7: TM01 | O7: TM23 | P7: TM45 | Q7: TM67 | R7: TM89
H8: 1 | I8: Focus Energy | N8: TM02 | O8: TM24 | P8: TM46 | Q8: TM68 | R8: TM90
H9: 1 | I9: Confusion | N9: TM03 | O9: TM25 | P9: TM47 | Q9: TM69 | R9: TM91
H10: 1 | I10: Incinerate | N10: TM04 | O10: TM26 | P10: TM48 | Q10: TM70 | R10: TM92
H11: 1 | I11: Quick Attack | N11: TM05 | O11: TM27 | P11: TM49 | Q11: TM71 | R11: TM93
B12: #494 Victini | H12: 9 | I12: Endure | N12: TM06 | O12: TM28 | P12: TM50 | Q12: TM72 | R12: TM94
A13: Type | B13: Psychic | C13: Fire | H13: 17 | I13: Headbutt | N13: TM07 | O13: TM29 | P13: TM51 | Q13: TM73 | R13: TM95
A14: HP | C14: 100 | H14: 25 | I14: Flame Charge | N14: TM08 | O14: TM30 | P14: TM52 | Q14: TM74 | R14: HM01
A15: Attack | C15: 100 | H15: 33 | I15: Reversal | N15: TM09 | O15: TM31 | P15: TM53 | Q15: TM75 | R15: HM02
A16: Defence | C16: 100 | H16: 41 | I16: Flame Burst | N16: TM10 | O16: TM32 | P16: TM54 | Q16: TM76 | R16: HM03
A17: SpAtk | C17: 100 | H17: 49 | I17: Zen Headbutt | N17: TM11 | O17: TM33 | P17: TM55 | Q17: TM77 | R17: HM04
A18: SpDef | C18: 100 | H18: 57 | I18: Inferno | N18: TM12 | O18: TM34 | P18: TM56 | Q18: TM78 | R18: HM05
A19: Speed | C19: 100 | H19: 65 | I19: Double-edge | N19: TM13 | O19: TM35 | P19: TM57 | Q19: TM79 | R19: HM06
A20: Total | C20: =SUM(C14:C19) -> 600 | H20: 73 | I20: Flare Blitz | N20: TM14 | O20: TM36 | P20: TM58 | Q20: TM80
A21: Ability 1 | B21: Illumination (Victory Star) | H21: 81 | I21: Final Gambit | N21: TM15 | O21: TM37 | P21: TM59 | Q21: TM81
A22: Ability 2 | B22: - | H22: 89 | I22: Stored Power | N22: TM16 | O22: TM38 | P22: TM60 | Q22: TM82
A23: Ability 3 (HA) | B23: - | H23: 97 | I23: Overheat | N23: TM17 | O23: TM39 | P23: TM61 | Q23: TM83
A24: Evolution Changes | H24: 99 | I24: Psycho Boost | N24: TM18 | O24: TM40 | P24: TM62 | Q24: TM84
N25: TM19 | O25: TM41 | P25: TM63 | Q25: TM85
N26: TM20 | O26: TM42 | P26: TM64 | Q26: TM86
N27: TM21 | O27: TM43 | P27: TM65 | Q27: TM87
N28: TM22 | O28: TM44 | P28: TM66 | Q28: TM88
C35: (NEW) | E35: (NEW) | G35: (NEW) | K35: (NEW) | M35: (NEW)
H36: Snivy | J36: Servine | L36: Serperior | N36: Now Compatible With
H37: 1 | I37: Mud Slap | J37: 1 | K37: Mud Slap | L37: 1 | M37: Wrap | N37: TM24: Thunderbolt
H38: 1 | I38: Leer | J38: 1 | K38: Leer | L38: 1 | M38: Synthesis | N38: TM25: Thunder
H39: 1 | I39: Absorb | J39: 1 | K39: Absorb | L39: 1 | M39: Absorb | N39: TM72: Volt Switch
H40: 4 | I40: Glare | J40: 4 | K40: Glare | L40: 4 | M40: Glare | N40: TM73: Thunder Wave
H41: 7 | I41: Shock Wave | J41: 7 | K41: Shock Wave | L41: 7 | M41: Shock Wave | N41: TM93: Wild Charge
B42: #495 Snivy | D42: #496 Servine | F42: #497 Serperior | H42: 10 | I42: Mega Drain | J42: 10 | K42: Mega Drain | L42: 10 | M42: Mega Drain | N42: TM38: Fire Blast
A43: Type | B43: Grass | D43: Grass | E43: Electric | F43: Grass | G43: Electric | H43: 13 | I43: Leaf Tornado | J43: 13 | K43: Leaf Tornado | L43: 13 | M43: Leaf Tornado | N43: TM54: Breaking Swipe
A44: HP | B44: 5+ | C44: 50 | E44: 60 | F44: 15+ | G44: 90 | H44: 17 | I44: Leech Seed | J44: 17 | K44: Leech Seed | L44: 17 | M44: Leech Seed | N44: TM59: Incinerate
A45: Attack | B45: 20- | C45: 25 | D45: 20- | E45: 40 | F45: 25- | G45: 50 | H45: 20 | I45: Dragon Breath | J45: 20 | K45: Dragon Breath | L45: 20 | M45: Dragon Breath | N45: TM32: Dazzling Gleam
A46: Defence | C46: 55 | E46: 75 | G46: 95 | H46: 24 | I46: Volt Switch | J46: 24 | K46: Volt Switch | L46: 24 | M46: Volt Switch | N46: TM21: Aurora Beam
A47: SpAtk | B47: 17+ | C47: 62 | D47: 12+ | E47: 72 | F47: 17+ | G47: 92 | H47: 27 | I47: Giga Drain | J47: 27 | K47: Giga Drain | L47: 27 | M47: Giga Drain | N47: TM35: Flamethrower
A48: SpDef | C48: 55 | E48: 75 | G48: 95 | H48: 30 | I48: Swagger | J48: 30 | K48: Swagger | L48: 30 | M48: Swagger
A49: Speed | B49: 15+ | C49: 78 | D49: 15+ | E49: 98 | F49: 10+ | G49: 123 | H49: 33 | I49: Twister | J49: 33 | K49: Twister | L49: 33 | M49: Twister
A50: Total | B50: 17+ | C50: =SUM(C44:C49) -> 325 | D50: 7+ | E50: =SUM(E44:E49) -> 420 | F50: 17+ | G50: =SUM(G44:G49) -> 545 | H50: 36 | I50: Parabolic Zap | J50: 36 | K50: Parabolic Zap | L50: 36 | M50: Parabolic Zap
...

Sheet New Forms
B2: New Forms
B12: #19 Rattata | D12: #20 Raticate
A13: Type | B13: Normal | D13: Normal
A14: HP | B14: 15+ | C14: 45 | D14: 10+ | E14: 65
A15: Attack | B15: 10+ | C15: 66 | D15: 20+ | E15: 101
A16: Defence | B16: 15+ | C16: 50 | E16: 60
A17: SpAtk | C17: 25 | E17: 50
A18: SpDef | B18: 15+ | C18: 50 | E18: 70
A19: Speed | C19: 72 | D19: 20+ | E19: 117
A20: Total | B20: 40+ | C20: =SUM(C14:C19) -> 308 | D20: 50+ | E20: =SUM(E14:E19) -> 463
A21: Ability 1 | B21: Adaptability | D21: Adaptability
A22: Ability 2 | B22: Guts | D22: Guts
A23: Ability 3 (HA) | B23: Adaptability | D23: Adaptability
A24: Evolution Changes
H25: Rattata-Alola | J25: Raticate-Alola | N25: Now Compatible With
H26: 1 | I26: Tackle | J26: 1 | K26: Tackle | N26: TM01: Psychic Fangs
H27: 1 | I27: Tail Whip | J27: 1 | K27: Tail Whip | N27: TM40: Aerial Ace
H28: 4 | I28: Quick Attack | J28: 4 | K28: Quick Attack | N28: TM65: Shadow Claw
H29: 7 | I29: Screech | J29: 7 | K29: Screech | N29: TM87: Rock Climb
H30: 10 | I30: Bite | J30: 10 | K30: Bite | N30: TM45: Lunge
B31: #19 Rattata-Alola | D31: #20 Raticate-Alola | H31: 12 | I31: Flame Wheel | J31: 12 | K31: Flame Wheel
A32: Type | B32: Normal | C32: Dark | D32: Normal | E32: Dark | H32: 13 | I32: Hyper Fang | J32: 13 | K32: Hyper Fang
A33: HP | B33: 25+ | C33: 55 | E33: 75 | H33: 16 | I33: Nuzzle | J33: 16 | K33: Nuzzle
A34: Attack | C34: 56 | D34: 10+ | E34: 81 | H34: 19 | I34: Sucker Punch | J34: 19 | K34: Sucker Punch
A35: Defence | B35: 55+ | C35: 90 | D35: 40+ | E35: 110 | H35: 23 | I35: Fire Fang | J35: 23 | K35: Fire Fang
A36: SpAtk | C36: 25 | E36: 40 | H36: 23 | I36: Ice Fang | J36: 23 | K36: Ice Fang
A37: SpDef | C37: 35 | E37: 80 | H37: 23 | I37: Thunder Fang | J37: 23 | K37: Thunder Fang
A38: Speed | B38: 20- | C38: 52 | E38: 77 | H38: 28 | I38: Crunch | J38: 28 | K38: Crunch
A39: Total | B39: 60+ | C39: =SUM(C33:C38) -> 313 | D39: 50+ | E39: =SUM(E33:E38) -> 463 | H39: 34 | I39: U-Turn | J39: 34 | K39: U-Turn
A40: Ability 1 | B40: Thick Fat | D40: Thick Fat | H40: 39 | I40: Double-Edge | J40: 39 | K40: Double-Edge
A41: Ability 2 | B41: Hustle | D41: Hustle | H41: 44 | I41: Flail | J41: 44 | K41: Flail
A42: Ability 3 (HA) | B42: Strong Jaw | D42: Strong Jaw | H42: 54 | I42: Facade | J42: 54 | K42: Facade
A43: Evolution Changes | J43: 60 | K43: Skull Bash
J44: 70 | K44: Giga Impact
B56: #26 Raichu
A57: Type | B57: Electric | C57: Ground
A58: HP | C58: 60
A59: Attack | B59: 10+ | C59: 100
A60: Defence | C60: 55
A61: SpAtk | B61: 15+ | C61: 105
...

Sheet Theoretical Imports
B2: New Forms
H7: Chesnaught | N7: Now Compatible With
H8: 1
H9: 1
H10: 4
H11: 7
H12: 10
B13: #654 Chesnaught | H13: 12
A14: Type | B14: Grass | C14: Fighting | H14: 13
A15: HP | C15: 88 | H15: 16
A16: Attack | C16: 107 | H16: 19
A17: Defence | C17: 122 | H17: 23
A18: SpAtk | C18: 74 | H18: 23
A19: SpDef | C19: 75 | H19: 23
A20: Speed | C20: 64 | H20: 28
A21: Total | C21: =SUM(C15:C20) -> 530 | H21: 34
A22: Ability 1 | B22: Overgrow | H22: 39
A23: Ability 2 | B23: Iron Barbs | H23: 44
A24: Ability 3 (HA) | B24: Bulletproof | H24: 54
A25: Evolution Changes
H29: Delphox | N29: Now Compatible With
H30: 1
H31: 1
H32: 4
H33: 7
H34: 10
B35: #655 Delphox | H35: 12
A36: Type | B36: Fire | C36: Psychic | H36: 13
A37: HP | C37: 75 | H37: 16
A38: Attack | C38: 69 | H38: 19
A39: Defence | C39: 72 | H39: 23
A40: SpAtk | C40: 114 | H40: 23
A41: SpDef | C41: 100 | H41: 23
A42: Speed | C42: 104 | H42: 28
A43: Total | C43: =SUM(C37:C42) -> 534 | H43: 34
A44: Ability 1 | B44: Blaze | H44: 39
A45: Ability 2 | B45: Forewarn | H45: 44
A46: Ability 3 (HA) | B46: Magic Guard | H46: 54
A47: Evolution Changes
H52: Greninja | N52: Now Compatible With
...

Sheet Unova
K2: Victini
K3: 1 | L3: Searing Shot
K4: 1 | L4: Focus Energy
K5: 1 | L5: Confusion
K6: 1 | L6: Incinerate
K7: 1 | L7: Quick Attack
B8: #494 Victini | K8: 9 | L8: Endure
A9: Type | B9: Psychic | C9: Fire | D9: Type | G9: Type | K9: 17 | L9: Headbutt
A10: HP | C10: 100 | D10: HP | G10: HP | K10: 25 | L10: Flame Charge
A11: Attack | C11: 100 | D11: Attack | G11: Attack | K11: 33 | L11: Reversal
A12: Defence | C12: 100 | D12: Defence | G12: Defence | K12: 41 | L12: Flame Burst
A13: SpAtk | C13: 100 | D13: SpAtk | G13: SpAtk | K13: 49 | L13: Zen Headbutt
A14: SpDef | C14: 100 | D14: SpDef | G14: SpDef | K14: 57 | L14: Inferno
A15: Speed | C15: 100 | D15: Speed | G15: Speed | K15: 65 | L15: Double-edge
A16: Total | C16: =SUM(C10:C15) -> 600 | D16: Total | G16: Total | K16: 73 | L16: Flare Blitz
A17: Ability 1 | B17: Illumination (Victory Star) | D17: Ability 1 | G17: Ability 1 | K17: 81 | L17: Final Gambit
A18: Ability 2 | B18: - | D18: Ability 2 | G18: Ability 2 | K18: 89 | L18: Stored Power
A19: Ability 3 (HA) | B19: - | D19: Ability 3 (HA) | G19: Ability 3 (HA) | K19: 97 | L19: Overheat
A20: Evolution Changes | D20: Evolution Changes | G20: Evolution Changes | K20: 99 | L20: Psycho Boost
K24: Snivy | M24: Servine | O24: Serperior | Q24: Now Compatible With
K25: 1 | L25: Sweet Scent | M25: 1 | N25: Sweet Scent | O25: 1 | P25: Wrap | Q25: TM24: Thunderbolt
K26: 1 | L26: Leer | M26: 1 | N26: Leer | O26: 1 | P26: Synthesis | Q26: TM25: Thunder
K27: 1 | L27: Absorb | M27: 1 | N27: Absorb | O27: 1 | P27: Absorb | Q27: TM72: Volt Switch
K28: 4 | L28: Leech Seed | M28: 4 | N28: Leech Seed | O28: 4 | P28: Leech Seed | Q28: TM73: Thunder Wave
K29: 7 | L29: Shock Wave | M29: 7 | N29: Shock Wave | O29: 7 | P29: Shock Wave | Q29: TM93: Wild Charge
B30: #495 Snivy | E30: #496 Servine | H30: #497 Serperior | K30: 10 | L30: Mega Drain | M30: 10 | N30: Mega Drain | O30: 10 | P30: Mega Drain | Q30: TM38: Fire Blast
A31: Type | B31: Grass | D31: Type | E31: Grass | F31: Electric | G31: Type | H31: Grass | I31: Electric | K31: 13 | L31: Leaf Tornado | M31: 13 | N31: Leaf Tornado | O31: 13 | P31: Leaf Tornado | Q31: TM54: Breaking Swipe
A32: HP | B32: 5+ | C32: 50 | D32: HP | F32: 60 | G32: HP | H32: 15+ | I32: 90 | K32: 17 | L32: Gastro Acid | M32: 17 | N32: Gastro Acid | O32: 17 | P32: Gastro Acid | Q32: TM59: Incinerate
A33: Attack | C33: 45 | D33: Attack | F33: 60 | G33: Attack | I33: 75 | K33: 20 | L33: Flame Burst | M33: 20 | N33: Flame Burst | O33: 20 | P33: Flame Burst | Q33: TM32: Dazzling Gleam
A34: Defence | C34: 55 | D34: Defence | F34: 75 | G34: Defence | I34: 95 | K34: 24 | L34: Volt Switch | M34: 24 | N34: Volt Switch | O34: 24 | P34: Volt Switch | Q34: TM21: Aurora Beam
A35: SpAtk | B35: 17+ | C35: 62 | D35: SpAtk | E35: 12+ | F35: 72 | G35: SpAtk | H35: 17+ | I35: 92 | K35: 27 | L35: Giga Drain | M35: 27 | N35: Giga Drain | O35: 27 | P35: Giga Drain | Q35: TM35: Flamethrower
A36: SpDef | C36: 55 | D36: SpDef | F36: 75 | G36: SpDef | I36: 95 | K36: 30 | L36: Glare | M36: 30 | N36: Glare | O36: 30 | P36: Glare
A37: Speed | B37: 15+ | C37: 78 | D37: Speed | E37: 15+ | F37: 98 | G37: Speed | H37: 10+ | I37: 123 | K37: 33 | L37: Twister | M37: 33 | N37: Twister | O37: 33 | P37: Twister
A38: Total | B38: 37+ | C38: =SUM(C32:C37) -> 345 | D38: Total | E38: 27+ | F38: =SUM(F32:F37) -> 440 | G38: Total | H38: 42+ | I38: =SUM(I32:I37) -> 570 | K38: 36 | L38: Parabolic Zap | M38: 36 | N38: Parabolic Zap | O38: 36 | P38: Parabolic Zap
A39: Ability 1 | B39: Adaptability | D39: Ability 1 | E39: Adaptability | G39: Ability 1 | H39: Adaptability | K39: 39 | L39: Captivate | M39: 39 | N39: Captivate | O39: 39 | P39: Captivate
A40: Ability 2 | B40: - | D40: Ability 2 | E40: - | G40: Ability 2 | H40: - | M40: 42 | N40: Seething Cold | O40: 42 | P40: Seething Cold
A41: Ability 3 (HA) | B41: Contrary | D41: Ability 3 (HA) | E41: Contrary | G41: Ability 3 (HA) | H41: Contrary | M41: 46 | N41: Energy Ball | O41: 46 | P41: Energy Ball
A42: Evolution Changes | D42: Evolution Changes | G42: Evolution Changes | M42: 50 | N42: Thunderbolt | O42: 50 | P42: Thunderbolt
M43: 54 | N43: Swagger | O43: 54 | P43: Swagger
M44: 58 | N44: Draco Meteor | O44: 58 | P44: Draco Meteor
...

Sheet Colors
A1: Grass
A2: Water
A3: Dark
A4: Flying
A5: Normal | D5: Normal | E5: Electric | F5: Psychic | N5: Starter Choice | U5: Flocessy Gift
A6: Fire | C6: Rock
A7: Ground | C7: Ground | H7: Fighting | I7: Dark
A8: Electric
A9: Dragon
A10: Ghost | H10: Normal | I10: Steel
A11: Bug | C11: (Currents) | D11: New Grass or Bug color? | H11: Fire | I11: Rock
A12: Psychic | H12: Rock | I12: Electric | J12: Grass | K12: Dragon
A13: Fighting | H13: Psychic | I13: Ice | J13: Fairy
A14: Rock | N14: #498 Tepig | P14: #499 Pignite | R14: #500 Emboar | U14: #285 Shroomish | W14: #286 Breloom
A15: Steel | G15: Electric | H15: Flying | N15: Fire | P15: Fire | Q15: Dark | R15: Fire | S15: Dark | U15: Grass | W15: Grass | X15: Fighting
A16: Ice | D16: Poison | E16: Dragon | F16: Flying | O16: 65 | Q16: 90 | R16: 10+ | S16: 120 | V16: 60 | X16: 60
A17: Flying | N17: 11+ | O17: 74 | Q17: 93 | S17: 123 | U17: 20+ | V17: 60 | X17: 130
A18: Poison | H18: Fairy | I18: Poison | N18: 8+ | O18: 53 | P18: 11+ | Q18: 66 | R18: 15+ | S18: 80 | V18: 60 | W18: 20+ | X18: 100
A19: Fairy | E19: Ice | N19: 10- | O19: 35 | P19: 20- | Q19: 50 | R19: 28- | S19: 72 | U19: 20+ | V19: 60 | X19: 60
N20: 8+ | O20: 53 | P20: 11+ | Q20: 66 | R20: 15+ | S20: 80 | V20: 60 | W20: 10+ | X20: 70
E21: Ice | O21: 45 | Q21: 55 | S21: 65 | U21: 25+ | V21: 60 | X21: 70
D22: Rock | E22: Fairy | H22: Fairy | N22: 17+ | O22: =SUM(O16:O21) -> 325 | P22: 2+ | Q22: =SUM(Q16:Q21) -> 420 | R22: 12+ | S22: =SUM(S16:S21) -> 540 | U22: 55+ | V22: =SUM(V16:V21) -> 360 | W22: 30+ | X22: =SUM(X16:X21) -> 490
B23: Grass | C23: Fighting | D23: Water | N23: Intimidate | P23: Intimidate | R23: Intimidate | U23: Effect Spore | W23: Technician
A24: Normal | B24: Ghost | C24: Grass | N24: - | P24: - | R24: - | U24: Poison Heal | W24: Poison Heal
N25: Sheer Force | P25: Sheer Force | R25: Determined (Rock Head) | U25: Effect Spore | W25: Technician
E26: Rock
C28: Water
F29: Ice | G29: Electric
C30: Grass
C31: Ice
B32: Rock | C32: Fire
N34: #495 Snivy | P34: #496 Servine | R34: #497 Serperior | U34: #278 Wingull | W34: #279 Pelipper
N35: Grass | P35: Grass | Q35: Electric | R35: Grass | S35: Electric | U35: Water | V35: Flying | W35: Water | X35: Flying
N36: 3+ | O36: 50 | Q36: 60 | R36: 15+ | S36: 90 | U36: 20+ | V36: 60 | W36: 10+ | X36: 70
D37: Rock | N37: 20- | O37: 25 | P37: 25- | Q37: 35 | R37: 25- | S37: 50 | V37: 30 | X37: 50
D38: Rock | O38: 55 | Q38: 75 | S38: 95 | U38: 35+ | V38: 65 | W38: 10+ | X38: 110
N39: 22+ | O39: 67 | P39: 17+ | Q39: 77 | R39: 17+ | S39: 92 | U39: 20+ | V39: 75 | W39: 20+ | X39: 95
O40: 55 | Q40: 75 | S40: 95 | U40: 15+ | V40: 45 | W40: 20+ | X40: 90
N41: 10+ | O41: 73 | P41: 15+ | Q41: 98 | R41: 5+ | S41: 118 | V41: 85 | W41: 20+ | X41: 85
N42: 17+ | O42: =SUM(O36:O41) -> 325 | P42: 7+ | Q42: =SUM(Q36:Q41) -> 420 | R42: 12+ | S42: =SUM(S36:S41) -> 540 | U42: 90+ | V42: =SUM(V36:V41) -> 360 | W42: 80+ | X42: =SUM(X36:X41) -> 500
...

Sheet Redesign Ideas
B2: New Forms
H7: Pinsir | N7: Now Compatible With
H8: 1 | I8: Rock Throw | N8: TM62: Acrobatics
H9: 1 | I9: Quick Attack | N9: TM76: Struggle Bug
H10: 7 | I10: Bug Bite | N10: TM84: Poison Jab
H11: 10 | I11: Stomp | N11: TM47: Low Sweep
H12: 13 | I12: Harden | N12: TM77: Bug Buzz
B13: #127 Pinsir | D13: #477 Dusknoir | H13: 17 | I13: Storm Throw
A14: Type | B14: Bug | D14: Ghost | E14: Fighting | H14: 22 | I14: Scary Face
A15: HP | C15: 65 | D15: 30+ | E15: 75 | H15: 25 | I15: Skitter Smack
A16: Attack | C16: 125 | D16: 10+ | E16: 110 | H16: 28 | I16: Thrash
A17: Defence | B17: 20+ | C17: 120 | E17: 135 | H17: 32 | I17: Dig
A18: SpAtk | C18: 55 | E18: 65 | H18: 35 | I18: Block
A19: SpDef | B19: 30+ | C19: 100 | E19: 135 | H19: 37 | I19: Rage
A20: Speed | C20: 85 | E20: 45 | H20: 40 | I20: Lunge
A21: Total | B21: 50+ | C21: =SUM(C15:C20) -> 550 | D21: 40+ | E21: =SUM(E15:E20) -> 565 | H21: 43 | I21: Iron Defense
A22: Ability 1 | B22: Mold Breaker | D22: Patient (Analytic) | H22: 48 | I22: Close Combat
A23: Ability 2 | B23: Hustle | D23: Forewarn | H23: 51 | I23: High Horsepower
A24: Ability 3 (HA) | B24: Sturdy | D24: - | H24: 56 | I24: Flail
A25: Evolution Changes | D25: Level 60 | H25: 62 | I25: Guillotine
H26: 65 | I26: Megahorn
H27: 71 | I27: Headlong Rush
H28: 79 | I28: Swords Dance
H34: Dwebble | J34: Crustle | N34: Now Compatible With
H35: 1 | I35: Harden | J35: 1 | K35: Accelerock | N35: TM54: Breaking Swipe
H36: 1 | I36: Accelerock | J36: 1 | K36: Clamp | N36: TM68: Avalanche
H37: 5 | I37: Bug Bite | J37: 5 | K37: Bug Bite | N37: TM89: U-Turn
H38: 7 | I38: Smack Down | J38: 7 | K38: Smack Down
H39: 11 | I39: Faint Attack | J39: 11 | K39: Faint Attack
B40: #557 Dwebble | D40: #558 Crustle | H40: 14 | I40: Rock Tomb | J40: 14 | K40: Rock Tomb
A41: Type | B41: Bug | C41: Ground | D41: Bug | E41: Ground | H41: 17 | I41: Rock Polish | J41: 17 | K41: Rock Polish
A42: HP | C42: 50 | E42: 70 | H42: 19 | I42: X-Scissor | J42: 19 | K42: X-Scissor
A43: Attack | B43: 10+ | C43: 75 | D43: 10+ | E43: 105 | H43: 22 | I43: Body Press | J43: 22 | K43: Body Press
A44: Defence | B44: 20+ | C44: 105 | D44: 20+ | E44: 145 | H44: 25 | I44: Razor Shell | J44: 25 | K44: Razor Shell
A45: SpAtk | C45: 35 | E45: 65 | H45: 27 | I45: Rock Slide | J45: 27 | K45: Rock Slide
A46: SpDef | B46: 10+ | C46: 45 | E46: 75 | H46: 32 | I46: Drill Run | J46: 32 | K46: Drill Run
A47: Speed | C47: 55 | E47: 45 | H47: 35 | I47: Lunge | J47: 35 | K47: Lunge
A48: Total | B48: 40+ | C48: =SUM(C42:C47) -> 365 | D48: 10+ | E48: =SUM(E42:E47) -> 505 | H48: 39 | I48: Tickle | J48: 39 | K48: Tickle
A49: Ability 1 | B49: Sturdy | D49: Sturdy | H49: 43 | I49: Heavy Slam | J49: 43 | K49: Heavy Slam
A50: Ability 2 | B50: Shell Armor | D50: Shell Armor | H50: 46 | I50: Stone Edge | J50: 46 | K50: Stone Edge
...

Sheet Type Changes
B2: Typing Changes
B4: The following Pokemon have had their typing's changed to create a fresh and unique metagame for both players and enemies in Cascade White.
B5: My priority for each change was in making mechanically interesting tools to play with, with less (but not 0) consideration for theming or flavor.
B8: Pokémon | C8: Old Typing | F8: New Typing
B9: Charmeleon | C9: Fire | F9: Fire | G9: Dragon
B10: Charizard | C10: Fire | D10: Flying | F10: Fire | G10: Dragon
B12: Wartortle | C12: Water | F12: Water | G12: Steel
B13: Blastoise | C13: Water | F13: Water | G13: Steel
B15: Pidgey | C15: Normal | D15: Flying | F15: Flying
B16: Pidgeotto | C16: Normal | D16: Flying | F16: Flying
B17: Pidgeot | C17: Normal | D17: Flying | F17: Flying
B19: Spearow | C19: Normal | D19: Flying | F19: Dark | G19: Flying
B20: Fearow | C20: Normal | D20: Flying | F20: Dark | G20: Flying
B22: Ekans | C22: Poison | F22: Poison | G22: Dragon
B23: Arbok | C23: Poison | F23: Poison | G23: Dragon
B25: Raichu | C25: Electric | F25: Electric | G25: Ground
B27: Vulpix | C27: Fire | F27: Fire | G27: Fairy
B28: Ninetales | C28: Fire | F28: Fire | G28: Fairy
B30: Igglybuff | C30: Normal | D30: Fairy | F30: Fairy | G30: Flying
B31: Jigglypuff | C31: Normal | D31: Fairy | F31: Fairy | G31: Flying
B32: Wigglytuff | C32: Normal | D32: Fairy | F32: Fairy | G32: Flying
B34: Oddish | C34: Grass | D34: Poison | F34: Fairy | G34: Poison
B35: Gloom | C35: Grass | D35: Poison | F35: Fairy | G35: Poison
