Workbook

Sheet Overview
B2: Pokemon Change Docs
B5: These documents will outline all the changes made to the mechanics of the game: including all changes to the stats, typings, abilities, and learnsets of all 649 Pokemon.
B7: Pokemon are grouped together by evolution line, placed in the generation where said line was introduced. For example, Pichu is in Kanto because Pikachu was introduced in Gen 1.
B9: You can find full documentation on moves, abilities, and typing changes on their associated tabs!
B13: Note! | C13: Normal Types are immune to Curse, Psychic types are immune to confusion
B15: Note! | C15: Ice Types get 1.5x defense in Hail.
B17: Hidden Abilities | C17: Wild Pokemon have a 10% chance to be found with their hidden ability if it's unique from their other abilities.
B21: Move Changes | E21: Ability Changes | H21: Typing Changes
B25: Kanto: #1-151
B28: Johto: #152-251
B31: Hoenn: #252-386
B34: Sinnoh: #387-493
B37: Unova: #494-649

Sheet Kanto
B2: Kanto: #1-151 | I2: Note!
I3: Because evolution lines are grouped together, some pokemon from later generations are here.
B4: *note, evolution lines are grouped together, so some gen 2 and 4 mons are here
H9: Bulbasaur | J9: Ivysaur | L9: Venusaur | N9: Now Compatible With
H10: 1 | I10: Vine Whip | J10: 1 | K10: Vine Whip | L10: 1 | M10: Wrap | N10: TM34: Sludge Wave
H11: 4 | I11: Sweet Scent | J11: 4 | K11: Sweet Scent | L11: 1 | M11: Sweet Scent | N11: TM57: Weather Ball
H12: 7 | I12: Leech Seed | J12: 7 | K12: Leech Seed | L12: 1 | M12: Leech Seed | N12: TM85: Play Rough
H13: 10 | I13: Mega Drain | J13: 10 | K13: Mega Drain | L13: 1 | M13: Spit Up | N13: TM63: Slam
H14: 13 | I14: Poisonpowder | J14: 13 | K14: Poisonpowder | L14: 13 | M14: Poisonpowder | N14: TM54: Breaking Swipe
B15: #1 Bulbasaur | D15: # 2 Ivysaur | F15: #3 Venusaur | H15: 13 | I15: Stun Spore | J15: 13 | K15: Stun Spore | L15: 13 | M15: Stun Spore | N15: Tutor: Earth Power
A16: Type | B16: Grass | C16: Poison | D16: Grass | E16: Poison | F16: Grass | G16: Poison | H16: 15 | I16: Venoshock | J16: 15 | K16: Venoshock | L16: 15 | M16: Venoshock | N16: TM05: Knock Off
A17: HP | C17: 45 | E17: 60 | G17: 80 | H17: 19 | I17: Leaf Tornado | J17: 19 | K17: Leaf Tornado | L17: 19 | M17: Leaf Tornado
A18: Attack | B18: 13- | C18: 36 | D18: 15- | E18: 47 | F18: 15- | G18: 67 | H18: 23 | I18: Bulldoze | J18: 23 | K18: Bulldoze | L18: 23 | M18: Bulldoze
A19: Defence | B19: 10+ | C19: 59 | D19: 15+ | E19: 78 | F19: 15+ | G19: 98 | H19: 27 | I19: Synthesis | J19: 27 | K19: Synthesis | L19: 27 | M19: Synthesis
A20: SpAtk | C20: 65 | D20: 5+ | E20: 85 | F20: 5+ | G20: 105 | H20: 32 | I20: Petal Dance | J20: 32 | K20: Petal Dance | L20: 32 | M20: Petal Dance
A21: SpDef | B21: 10+ | C21: 75 | D21: 15+ | E21: 95 | F21: 15+ | G21: 115 | H21: 36 | I21: Earth Power | J21: 36 | K21: Earth Power | L21: 36 | M21: Earth Power
A22: Speed | C22: 45 | E22: 60 | G22: 80 | J22: 40 | K22: Sleep Powder | L22: 40 | M22: Sleep Powder
A23: Total | B23: 7+ | C23: =SUM(C17:C22) -> 325 | D23: 15+ | E23: =SUM(E17:E22) -> 425 | F23: 20+ | G23: =SUM(G17:G22) -> 545 | J23: 43 | K23: Roar | L23: 43 | M23: Roar
A24: Ability 1 | B24: Thick Fat | D24: Thick Fat | F24: Thick Fat | J24: 46 | K24: Amnesia | L24: 46 | M24: Amnesia
A25: Ability 2 | B25: Overgrow | D25: Overgrow | F25: Overgrow | J25: 50 | K25: Sludge Bomb | L25: 50 | M25: Sludge Bomb
A26: Ability 3 (HA) | B26: Huge Power | D26: Huge Power | F26: Huge Power | J26: 53 | K26: Power Whip | L26: 53 | M26: Power Whip
A27: Evolution Changes | F27: Level 36 | L27: 57 | M27: Growth
L28: 62 | M28: Leaf Storm
L29: 70 | M29: Hyper Beam
H33: Charmander | J33: Charmeleon | L33: Charizard | N33: Now Compatible With
H34: 1 | I34: Ember | J34: 1 | K34: Ember | L34: 1 | M34: Sky Attack | N34: TM62: Acrobatics
H35: 1 | I35: Growl | J35: 1 | K35: Growl | L35: 1 | M35: Earthquake | N35: TM47: Low Sweep
H36: 7 | I36: Smokescreen | J36: 7 | K36: Smokescreen | L36: 1 | M36: Steel Wing | N36: TM54: Breaking Swipe
H37: 10 | I37: Flame Wheel | J37: 10 | K37: Flame Wheel | L37: 10 | M37: Flame Wheel | N37: TM48: Mystical Fire
H38: 13 | I38: Metal Claw | J38: 13 | K38: Metal Claw | L38: 13 | M38: Metal Claw | N38: TM63: Slam
B39: #4 Charmander | D39: #5 Charmeleon | F39: #6 Charizard | H39: 16 | I39: Breaking Swipe | J39: 16 | K39: Breaking Swipe | L39: 16 | M39: Breaking Swipe | N39: Tutor: Dragon Pulse
A40: Type | B40: Fire | C40: Dragon | D40: Fire | E40: Dragon | F40: Fire | G40: Dragon | H40: 20 | I40: Slash | J40: 20 | K40: Slash | L40: 20 | M40: Slash | N40: Tutor: Dual Chop
A41: HP | B41: 11+ | C41: 50 | E41: 58 | G41: 78 | H41: 24 | I41: Flamethrower | J41: 24 | K41: Flamethrower | L41: 24 | M41: Flamethrower | N41: TM18: Scorching Sands
A42: Attack | B42: 15+ | C42: 67 | D42: 30+ | E42: 89 | F42: 35+ | G42: 119 | H42: 27 | I42: Scary Face | J42: 27 | K42: Scary Face | L42: 27 | M42: Scary Face | N42: TM12: Taunt
A43: Defence | C43: 43 | E43: 58 | G43: 78 | H43: 30 | I43: Thunderpunch | J43: 30 | K43: Thunderpunch | L43: 30 | M43: Thunderpunch | N43: Tutor: Draco Meteor
A44: SpAtk | B44: 10- | C44: 50 | D44: 10- | E44: 70 | F44: 29- | G44: 80 | H44: 33 | I44: Devour | J44: 33 | K44: Devour | L44: 33 | M44: Devour
A45: SpDef | C45: 50 | E45: 65 | G45: 85 | H45: 36 | I45: Sky Drop | J45: 36 | K45: Sky Drop | L45: 36 | M45: Sky Drop
A46: Speed | C46: 65 | D46: 5+ | E46: 85 | F46: 5+ | G46: 105 | H46: 40 | I46: Dragon Tail | J46: 40 | K46: Dragon Tail | L46: 40 | M46: Dragon Tail
A47: Total | B47: 16+ | C47: =SUM(C41:C46) -> 325 | D47: 20+ | E47: =SUM(E41:E46) -> 425 | F47: 16+ | G47: =SUM(G41:G46) -> 545 | H47: 43 | I47: Work Up | J47: 43 | K47: Work Up | L47: 43 | M47: Work Up
A48: Ability 1 | B48: Flash Fire | D48: Flash Fire | F48: Levitate | H48: 46 | I48: Fire Lash | J48: 46 | K48: Fire Lash | L48: 46 | M48: Fire Lash
...

Sheet Johto
A1: F
B2: Johto: #152-251 | I2: Note! | K2: Kanto
I3: Because evolution lines are grouped together, the following Johto pokemon are not on this sheet.
B4: *note, evolution lines are grouped together, so some gen 3 and 4 mons are here
K6: Igglybuff, Cleffa, Pichu, Bellossom, Politoed, Espeon, Umbreon, Slowking, Steelix, Scizor, Kingdra, Porygon2, Tyrogue, Hitmontop, Smoochum, Elekid, Magby, Blissey
H9: Chikorita | J9: Bayleef | L9: Meganium | N9: Now Compatible With
H10: 1 | I10: Tackle | J10: 1 | K10: Tackle | L10: 1 | M10: Skull Bash | N10: TM85: Play Rough
H11: 1 | I11: Growl | J11: 1 | K11: Growl | L11: 1 | M11: Sleep Powder | N11: TM32: Dazzling Gleam
H12: 7 | I12: Poisonpowder | J12: 7 | K12: Poisonpowder | L12: 7 | M12: Poisonpowder | N12: TM48: Mystical Fire
H13: 10 | I13: Stomp | J13: 10 | K13: Stomp | L13: 10 | M13: Stomp | N13: TM29: Psychic
H14: 13 | I14: Bullet Seed | J14: 13 | K14: Bullet Seed | L14: 13 | M14: Bullet Seed | N14: TM79: Body Press
B15: #152 Chikorita | D15: #153 Bayleef | F15: #154 Meganium | H15: 15 | I15: Safeguard | J15: 15 | K15: Safeguard | L15: 15 | M15: Safeguard | N15: TM92: Solar Blade
A16: Type | B16: Grass | D16: Grass | E16: Fairy | F16: Grass | G16: Fairy | H16: 18 | I16: Natural Gift | J16: 18 | K16: Natural Gift | L16: 18 | M16: Natural Gift | N16: TM03: Psyshock
A17: HP | C17: 45 | E17: 60 | G17: 80 | H17: 23 | I17: Dazzling Gleam | J17: 23 | K17: Dazzling Gleam | L17: 23 | M17: Dazzling Gleam
A18: Attack | B18: 16+ | C18: 66 | D18: 20+ | E18: 82 | F18: 20+ | G18: 102 | H18: 26 | I18: Horn Leech | J18: 26 | K18: Horn Leech | L18: 26 | M18: Horn Leech
A19: Defence | C19: 65 | E19: 80 | G19: 100 | H19: 30 | I19: Light Screen | J19: 30 | K19: Light Screen | L19: 30 | M19: Light Screen
A20: SpAtk | C20: 49 | E20: 63 | G20: 83 | H20: 30 | I20: Reflect | J20: 36 | K20: Reflect | L20: 36 | M20: Reflect
A21: SpDef | C21: 65 | E21: 80 | G21: 100 | H21: 36 | I21: Petal Dance | J21: 36 | K21: Petal Dance | L21: 36 | M21: Petal Dance
A22: Speed | C22: 45 | E22: 60 | G22: 80 | H22: 40 | I22: Heart Stamp | J22: 40 | K22: Heart Stamp | L22: 40 | M22: Heart Stamp
A23: Total | B23: 16+ | C23: =SUM(C17:C22) -> 335 | D23: 20+ | E23: =SUM(E17:E22) -> 425 | F23: 20+ | G23: =SUM(G17:G22) -> 545 | H23: 44 | I23: Synthesis | J23: 44 | K23: Synthesis | L23: 44 | M23: Synthesis
A24: Ability 1 | B24: Overgrow | D24: Overgrow | F24: Overgrow | J24: 50 | K24: Earthquake | L24: 50 | M24: Earthquake
A25: Ability 2 | B25: Healer | D25: Healer | F25: Healer | J25: 54 | K25: Petal Blizzard | L25: 54 | M25: Petal Blizzard
A26: Ability 3 (HA) | B26: Natural Cure | D26: Natural Cure | F26: Flower Gift | J26: 60 | K26: Growth | L26: 60 | M26: Growth
A27: Evolution Changes | F27: Level 36 | J27: 62 | K27: Headlong Rush | L27: 62 | M27: Headlong Rush
L28: 68 | M28: Giga Impact
H32: Cyndaquil | J32: Quilava | L32: Typhlosion | N32: Now Compatible With
H33: 1 | I33: Quick Attack | J33: 1 | K33: Quick Attack | L33: 1 | M33: Magma Storm | N33: Tutor: Earth Power
H34: 1 | I34: Leer | J34: 1 | K34: Leer | L34: 1 | M34: Sand Tomb | N34: TM48: Mystical Fire
H35: 4 | I35: Smokescreen | J35: 4 | K35: Smokescreen | L35: 4 | M35: Smokescreen
H36: 6 | I36: Flame Wheel | J36: 6 | K36: Flame Wheel | L36: 6 | M36: Flame Wheel
H37: 10 | I37: Dig | J37: 10 | K37: Dig | L37: 10 | M37: Dig
B38: #155 Cyndaquil | D38: #156 Quilava | F38: #157 Typhlosion | H38: 13 | I38: Extrasensory | J38: 13 | K38: Extrasensory | L38: 13 | M38: Extrasensory
A39: Type | B39: Fire | D39: Fire | E39: Ground | F39: Fire | G39: Ground | H39: 17 | I39: Mud Shot | J39: 17 | K39: Mud Shot | L39: 17 | M39: Mud Shot
A40: HP | C40: 39 | E40: 58 | G40: 78 | H40: 20 | I40: Infernal Parade | J40: 20 | K40: Infernal Parade | L40: 20 | M40: Infernal Parade
A41: Attack | C41: 52 | E41: 64 | G41: 84 | H41: 24 | I41: Endure | J41: 24 | K41: Endure | L41: 24 | M41: Endure
A42: Defence | C42: 43 | E42: 58 | G42: 78 | H42: 27 | I42: Gyro Ball | J42: 27 | K42: Gyro Ball | L42: 27 | M42: Gyro Ball
A43: SpAtk | B43: 16+ | C43: 76 | D43: 20+ | E43: 100 | F43: 11+ | G43: 120 | H43: 30 | I43: Scorching Sands | J43: 30 | K43: Scorching Sands | L43: 30 | M43: Scorching Sands
A44: SpDef | C44: 50 | E44: 65 | G44: 85 | H44: 33 | I44: Defense Curl | J44: 33 | K44: Defense Curl | L44: 33 | M44: Defense Curl
A45: Speed | C45: 65 | E45: 80 | G45: 100 | H45: 36 | I45: Flare Blitz | J45: 36 | K45: Flare Blitz | L45: 36 | M45: Flare Blitz
A46: Total | B46: 11+ | C46: =SUM(C40:C45) -> 325 | D46: 20+ | E46: =SUM(E40:E45) -> 425 | F46: 11+ | G46: =SUM(G40:G45) -> 545 | H46: 40 | I46: Reversal | J46: 40 | K46: Reversal | L46: 40 | M46: Reversal
...

Sheet Hoenn
B2: Hoenn: #252-386 | I2: Note! | K2: Johto
I3: Because evolution lines are grouped together, the following Hoenn pokemon are not on this sheet.
B4: *note, evolution lines are grouped together, so some gen 4 mons are here
K6: Azurill, Wynaut
H9: Treecko | J9: Grovyle | L9: Sceptile | N9: Now Compatible With
H10: 1 | I10: Quick Attack | J10: 1 | K10: Quick Attack | L10: 1 | M10: Clanging Scales | N10: TM89: U-turn
H11: 1 | I11: Leer | J11: 1 | K11: Leer | L11: 1 | M11: Wood Hammer | N11: Tutor Draco Meteor
H12: 6 | I12: Breaking Swipe | J12: 6 | K12: Breaking Swipe | L12: 1 | M12: Psyblade
H13: 9 | I13: Razor Winds | J13: 9 | K13: Razor Winds | L13: 9 | M13: Razor Winds
H14: 13 | I14: Razor Leaf | J14: 13 | K14: Razor Leaf | L14: 13 | M14: Razor Leaf
B15: #252 Treecko | D15: #253 Grovyle | F15: #254 Sceptile | H15: 16 | I15: Double Team | J15: 16 | K15: Double Team | L15: 16 | M15: Double Team
A16: Type | B16: Grass | D16: Grass | E16: Dragon | F16: Grass | G16: Dragon | H16: 19 | I16: U-Turn | J16: 19 | K16: U-Turn | L16: 19 | M16: U-Turn
A17: HP | C17: 40 | E17: 50 | G17: 70 | H17: 22 | I17: Leaf Tornado | J17: 22 | K17: Leaf Tornado | L17: 22 | M17: Leaf Tornado
A18: Attack | B18: 20+ | C18: 65 | D18: 20+ | E18: 85 | F18: 15+ | G18: 100 | H18: 25 | I18: Screech | J18: 25 | K18: Screech | L18: 25 | M18: Screech
A19: Defence | C19: 35 | E19: 45 | G19: 65 | H19: 29 | I19: Dragon Breath | J19: 29 | K19: Dragon Breath | L19: 29 | M19: Dragon Breath
A20: SpAtk | C20: 65 | E20: 85 | G20: 105 | H20: 33 | I20: Air Slash | J20: 33 | K20: Air Slash | L20: 33 | M20: Air Slash
A21: SpDef | C21: 55 | E21: 65 | G21: 85 | H21: 36 | I21: Trop Kick | J21: 36 | K21: Trop Kick | L21: 36 | M21: Trop Kick
A22: Speed | C22: 70 | D22: ````````````````````````````````````````````````````````````````````````````````````````````````````````````````````````````````````````````````````````````````````````````````````````````````````````````````````````````````````````````````````````````````````````````````````````````````````````````````````````````````````````````````````````````````````````````````````````````````````````````````````````````````````````````````````````````````````````````````````````````````````````````````````````````````````````````````````````````````````````````````````````````````````````````````````````````````````````````````````````````````````````````````````````````````````````````````````````````````````````````````````````````````````````````````````````````````````````````````````````````````````````````````````````````````````````````````````````````````````````````````````````````````````````````````````````````````````````````````````````````````````````````````````````````````````````````````````````````````````````````````````````````````````````````````````````````````````````````````````````````````````````````````````````````````````````````````````````````````````````````````````````````````````````````````````````````````````````````````````````````````````````````````````````````````````````````````````````````````````````````````````````````````````````````````````````````````````````````````````````````````````````````````````````````````````````````````````````````````````````````````````````````````````````````````````````````````````````````````````````````````````````````````````````````````````````````````````````````````````````````````````````````````````````````````````````````````````````````````````````````````````````````````````````````````````````````````````````````````````````````````````````````````````````````````````````````````````````````````````````````````````````````````````````````````````````````````````````````````````````````````````````````````````````````````````````````````````````````````````````````````````````````````````````````````````````````````````````````````````````````````````````````````````````````````````````````````````````````````````````````````````````````````````````````````````````````````````````````````````````````````````````````````````````````````````````````````````````````````````````````````````````````````````````````````````````````````````````````````````````````````````````````````````````````````````````````````````````````````````````````````````````````````````````````````````````````````````````````````````````````````````````````````````````````````````````````````````````````````````````````````````````````````````````````````````````````````````````````````````````````````````````````````````````````````````````````````````````````````````````````````````````````````````````````````````````````````````````````````````````````````````````````````````````````````````````````````````````````````````````````````````````````````````````````````````````````````````````````````````````````````````````````````````````````````````````````````````````````````````````````````````````````````````````````````````````````````````````````````````````````````````````````````````````````````````````````````````````````````````````````````````````````````````````````````````````````````````````````````````````````````````````````````````````````````````````````````````````````````````````````````````````````````````````````````````````````````````````````````````````````````````````````````````````````````````````````````````````````````````````````````````````````````````````````````````````````````````````````````````````````````````````````````````````````````````````````````````````````````````````````````````````````````````````````````````````````````````````````````````````````````````````````````````````````````````````````````````````````````````````````````````````````````````````````````````````````````````````````````````````````````````````````````````````````````````````````````````````````````````````````````````````````````````````````````````````````````````````````````````````````````````````````````````````````````````````````````````````````````````````````````````````````````````````````````````````````````````````````````````````````````````````````````````````````````````````````````````````````````````````````````````````````````````````````````````````````````````````````````````````````````````````````````````````````````````````````````````````````````````````````````````````````````````````````````````````````````````````````````````````````````````````````````````````````````````````````````````````````````````````````````````````````````````````````````````````````````````````````````````````````````````````````````````````````````````````````````````````````````````````````````````````````````````````````````````````````````````````````````````````````````````````````````````````````````````````````````````````````````````````````````````````````````````````````````````````````````````````````````````````````````````````````````````````````````````````````````````````````````````````````````````````````````````````````````````````````````````````````````````````````````````````````````````````````````````````````````````````````````````````````````````````````````````````````````````````````````````````````````````````````````````````````````````````````````````````````````````````````````````````````````````````````````````````````````````````````````````````````````````````````````````````````````````````````````````````````````````````````````````````````````````````````````````````````````````````````````````````````````````````````````````````````````````````````````````````````````````````5` | E22: 95 | G22: 120 | H22: 38 | I22: Weather Ball | J22: 38 | K22: Weather Ball | L22: 38 | M22: Weather Ball
A23: Total | B23: 20+ | C23: =SUM(C17:C22) -> 330 | D23: 20+ | E23: =SUM(E17:E22) -> 425 | F23: 15+ | G23: =SUM(G17:G22) -> 545 | H23: 42 | I23: Dragon Pulse | J23: 42 | K23: Dragon Pulse | L23: 42 | M23: Dragon Pulse
A24: Ability 1 | B24: Technician | D24: Hyper Cutter | F24: Hyper Cutter | H24: 45 | I24: Slam | J24: 45 | K24: Slam | L24: 45 | M24: Slam
A25: Ability 2 | B25: Overgrow | D25: Overgrow | F25: Overgrow | H25: 48 | I25: Leaf Blade | J25: 48 | K25: Leaf Blade | L25: 48 | M25: Leaf Blade
A26: Ability 3 (HA) | B26: Unburden | D26: Unburden | F26: Exploit (Download) | J26: 54 | K26: Fake Out | L26: 54 | M26: Fake Out
A27: Evolution Changes | J27: 58 | K27: Guillotine | L27: 58 | M27: Guillotine
L28: 65 | M28: Leaf Storm
L29: 77 | M29: Draco Meteor
H33: Torchic | J33: Combusken | L33: Blaziken | N33: Now Compatible With
H34: 1 | I34: Pluck | J34: 1 | K34: Pluck | L34: 1 | M34: Reversal | N34: TM89: U-turn
H35: 1 | I35: Quick Attack | J35: 1 | K35: Quick Attack | L35: 1 | M35: Close Combat | N35: TM18: Scorching Sands
H36: 7 | I36: Sand Attack | J36: 7 | K36: Sand Attack | L36: 1 | M36: Flare Blitz | N36: TM07: Drain Punch
H37: 10 | I37: Natural Gift | J37: 10 | K37: Natural Gift | L37: 10 | M37: Natural Gift | N37: HM02: Fly
H38: 13 | I38: Flame Burst | J38: 13 | K38: Flame Burst | L38: 13 | M38: Flame Burst | N38: TM58: Hurricane
B39: #255 Torchic | D39: #256 Combusken | F39: #257 Blaziken | H39: 16 | I39: Sky Uppercut | J39: 16 | K39: Sky Uppercut | L39: 16 | M39: Sky Uppercut | N39: TM11: Air Slash
A40: Type | B40: Fire | D40: Fire | E40: Flying | F40: Fire | G40: Flying | H40: 19 | I40: Aerial Ace | J40: 19 | K40: Aerial Ace | L40: 19 | M40: Aerial Ace | N40: TM62: Acrobatics
A41: HP | C41: 45 | E41: 60 | G41: 80 | H41: 22 | I41: Endure | J41: 22 | K41: Endure | L41: 22 | M41: Endure | N41: TM46: Aura Sphere
A42: Attack | C42: 60 | E42: 85 | G42: 120 | H42: 25 | I42: U-turn | J42: 25 | K42: U-turn | L42: 25 | M42: U-turn
A43: Defence | C43: 40 | E43: 60 | G43: 70 | H43: 28 | I43: Jump Kick | J43: 28 | K43: Jump Kick | L43: 28 | M43: Jump Kick
A44: SpAtk | C44: 70 | E44: 85 | G44: 110 | H44: 31 | I44: Bounce | J44: 31 | K44: Bounce | L44: 31 | M44: Bounce
A45: SpDef | C45: 50 | E45: 60 | G45: 70 | H45: 34 | I45: Agility | J45: 34 | K45: Agility | L45: 34 | M45: Agility
A46: Speed | B46: 15+ | C46: 60 | D46: 20+ | E46: 75 | F46: 15+ | G46: 95 | H46: 40 | I46: Fire Spin | J46: 40 | K46: Fire Spin | L46: 40 | M46: Fire Spin
A47: Total | B47: 15+ | C47: =SUM(C41:C46) -> 325 | D47: 20+ | E47: =SUM(E41:E46) -> 425 | F47: 15+ | G47: =SUM(G41:G46) -> 545 | H47: 44 | I47: Feather Dance | J47: 44 | K47: Feather Dance | L47: 44 | M47: Feather Dance
...

Sheet Sinnoh
A1: Br
B2: Sinnoh: #387-493 | I2: Note! | K2: Kanto | M2: Hoenn | N2: Johto
I3: Because evolution lines are grouped together, the following Sinnoh pokemon are not on this sheet.
K6: Happiny, Munchlax, Magnezone, Lickilicky, Rhyperior, PorygonZ, Porygon-Z, Tangrowth, Electivire, Magmortar, Leafeon, Glaceon, Mime Jr, Mime Jr. | M6: Budew, Roserade, Chingling, Gallade, Probopass, Dusknoir, Froslass | N6: Ambipom, Mismagius, Honchkrow, Bonsly, Mantyke, Weavile, Togekiss, Yanmega, Gliscor, Mamoswine
H9: Turtwig | J9: Grotle | L9: Torterra | N9: Now Compatible With
H10: 1 | I10: Harden | J10: 1 | K10: Harden | L10: 1 | M10: Giga Impact | N10: TM68: Avalanche
H11: 1 | I11: Mega Drain | J11: 1 | K11: Mega Drain | L11: 1 | M11: Headlong Rush | N11: TM01: Psychic Fangs
H12: 7 | I12: Razor Leaf | J12: 7 | K12: Razor Leaf | L12: 1 | M12: Ingrain
H13: 10 | I13: Stomp | J13: 10 | K13: Stomp | L13: 1 | M13: Skull Bash
H14: 13 | I14: Bite | J14: 13 | K14: Bite | L14: 13 | M14: Bite
B15: #387 Turtwig | D15: #388 Grotle | F15: #389 Torterra | H15: 16 | I15: Stompin Tantrum | J15: 16 | K15: Stompin Tantrum | L15: 16 | M15: Stompin Tantrum
A16: Type | B16: Grass | D16: Grass | E16: Ground | F16: Grass | G16: Ground | H16: 19 | I16: Giga Drain | J16: 19 | K16: Giga Drain | L16: 19 | M16: Giga Drain
A17: HP | C17: 55 | E17: 75 | G17: 95 | H17: 22 | I17: Razor Shell | J17: 22 | K17: Razor Shell | L17: 22 | M17: Razor Shell
A18: Attack | C18: 68 | E18: 89 | G18: 109 | H18: 25 | I18: Crunch | J18: 25 | K18: Crunch | L18: 25 | M18: Crunch
A19: Defence | B19: 7+ | C19: 71 | D19: 10+ | E19: 95 | F19: 10+ | G19: 115 | H19: 29 | I19: Seed Bomb | J19: 29 | K19: Seed Bomb | L19: 29 | M19: Seed Bomb
A20: SpAtk | C20: 45 | E20: 55 | G20: 75 | H20: 32 | I20: Wide Guard | J20: 32 | K20: Wide Guard | L20: 32 | M20: Wide Guard
A21: SpDef | C21: 55 | D21: 10+ | E21: 75 | F21: 10+ | G21: 95 | H21: 36 | I21: Head Charge | J21: 36 | K21: Head Charge | L21: 36 | M21: Head Charge
A22: Speed | B22: 20+ | C22: 51 | E22: 36 | G22: 56 | H22: 40 | I22: Synthesis | J22: 40 | K22: Synthesis | L22: 40 | M22: Synthesis
A23: Total | B23: 7+ | C23: =SUM(C17:C22) -> 345 | D23: 20+ | E23: =SUM(E17:E22) -> 425 | F23: 20+ | G23: =SUM(G17:G22) -> 545 | J23: 44 | K23: Leaf Storm | L23: 44 | M23: Leaf Storm
A24: Ability 1 | B24: Shell Armor | D24: Shell Armor | F24: Shell Armor | J24: 46 | K24: Head Smash | L24: 46 | M24: Head Smash
A25: Ability 2 | B25: Overgrow | D25: Overgrow | F25: Rock Head | J25: 50 | K25: Earthquake | L25: 50 | M25: Earthquake
A26: Ability 3 (HA) | B26: Solid Rock | D26: Solid Rock | F26: Solid Rock | L26: 54 | M26: Wood Hammer
A27: Evolution Changes | F27: Level 36 | L27: 61 | M27: Rock Wrecker
L28: 66 | M28: Growth
L29: 70 | M29: Fissure
H33: Chimchar | J33: Monferno | L33: Infernape | N33: Now Compatible With
H34: 1 | I34: Torment | J34: 1 | K34: Torment | L34: 1 | M34: Focus Energy | N34: TM05: Knock Off
H35: 1 | I35: Ember | J35: 1 | K35: Ember | L35: 1 | M35: Fake Out | N35: TM07: Drain Punch
H36: 8 | I36: Mach Punch | J36: 8 | K36: Mach Punch | L36: 1 | M36: Ice Punch
H37: 10 | I37: Flame Wheel | J37: 10 | K37: Flame Wheel | L37: 10 | M37: Flame Wheel
H38: 14 | I38: Poison Jab | J38: 14 | K38: Poison Jab | L38: 14 | M38: Poison Jab
B39: #390 Chimchar | D39: #391 Monferno | F39: #392 Infernape | H39: 17 | I39: Switcheroo | J39: 17 | K39: Switcheroo | L39: 17 | M39: Switcheroo
A40: Type | B40: Fire | D40: Fire | E40: Fighting | F40: Fire | G40: Fighting | H40: 20 | I40: Force Palm | J40: 20 | K40: Force Palm | L40: 20 | M40: Force Palm
A41: HP | C41: 44 | E41: 64 | G41: 76 | H41: 23 | I41: Acrobatics | J41: 23 | K41: Acrobatics | L41: 23 | M41: Acrobatics
A42: Attack | C42: 58 | D42: 5+ | E42: 83 | G42: 104 | H42: 27 | I42: Taunt | J42: 27 | K42: Taunt | L42: 27 | M42: Taunt
A43: Defence | C43: 44 | E43: 52 | G43: 71 | H43: 30 | I43: Fire Punch | J43: 30 | K43: Fire Punch | L43: 30 | M43: Fire Punch
A44: SpAtk | C44: 58 | D44: 5+ | E44: 83 | G44: 104 | H44: 33 | I44: Slack Off | J44: 33 | K44: Slack Off | L44: 33 | M44: Slack Off
A45: SpDef | C45: 44 | E45: 52 | G45: 71 | H45: 36 | I45: Sky Uppercut | J45: 36 | K45: Sky Uppercut | L45: 36 | M45: Sky Uppercut
A46: Speed | B46: 16+ | C46: 77 | D46: 10+ | E46: 91 | F46: 11+ | G46: 119 | H46: 41 | I46: Thunder Punch | J46: 41 | K46: Thunder Punch | L46: 41 | M46: Thunder Punch
A47: Total | B47: 16+ | C47: =SUM(C41:C46) -> 325 | D47: 15+ | E47: =SUM(E41:E46) -> 425 | F47: 11+ | G47: =SUM(G41:G46) -> 545 | J47: 44 | K47: Fire Spin | L47: 44 | M47: Fire Spin
...

Sheet Unova
B2: Unova: #494-649
H7: Victini
H8: 1 | I8: Searing Shot
H9: 1 | I9: Focus Energy
H10: 1 | I10: Confusion
H11: 1 | I11: Incinerate
H12: 1 | I12: Quick Attack
B13: #494 Victini | H13: 9 | I13: Endure
A14: Type | B14: Psychic | C14: Fire | H14: 17 | I14: Headbutt
A15: HP | C15: 100 | H15: 25 | I15: Flame Charge
A16: Attack | C16: 100 | H16: 33 | I16: Reversal
A17: Defence | C17: 100 | H17: 41 | I17: Flame Burst
A18: SpAtk | C18: 100 | H18: 49 | I18: Zen Headbutt
A19: SpDef | C19: 100 | H19: 57 | I19: Inferno
A20: Speed | C20: 100 | H20: 65 | I20: Double-edge
A21: Total | C21: =SUM(C15:C20) -> 600 | H21: 73 | I21: Flare Blitz
A22: Ability 1 | B22: Illumination (Victory Star) | H22: 81 | I22: Final Gambit
A23: Ability 2 | B23: - | H23: 89 | I23: Stored Power
A24: Ability 3 (HA) | B24: - | H24: 97 | I24: Overheat
A25: Evolution Changes | H25: 99 | I25: Psycho Boost
H29: Snivy | J29: Servine | L29: Serperior | N29: Now Compatible With
H30: 1 | I30: Sweet Scent | J30: 1 | K30: Sweet Scent | L30: 1 | M30: Hyper Beam | N30: TM24: Thunderbolt
H31: 1 | I31: Mega Drain | J31: 1 | K31: Mega Drain | L31: 1 | M31: Overheat | N31: TM25: Thunder
H32: 4 | I32: Leech Seed | J32: 4 | K32: Leech Seed | L32: 1 | M32: Volt Tackle | N32: TM72: Volt Switch
H33: 7 | I33: Shock Wave | J33: 7 | K33: Shock Wave | L33: 7 | M33: Shock Wave | N33: TM73: Thunder Wave
H34: 10 | I34: Glare | J34: 10 | K34: Glare | L34: 10 | M34: Glare | N34: TM93: Wild Charge
B35: #495 Snivy | D35: #496 Servine | F35: #497 Serperior | H35: 13 | I35: Leaf Tornado | J35: 13 | K35: Leaf Tornado | L35: 13 | M35: Leaf Tornado | N35: TM38: Fire Blast
A36: Type | B36: Grass | D36: Grass | E36: Electric | F36: Grass | G36: Electric | H36: 17 | I36: Bind | J36: 17 | K36: Bind | L36: 17 | M36: Bind | N36: TM54: Breaking Swipe
A37: HP | B37: 5+ | C37: 50 | E37: 60 | F37: 15+ | G37: 90 | H37: 20 | I37: Seething Cold | J37: 20 | K37: Seething Cold | L37: 20 | M37: Seething Cold | N37: TM59: Incinerate
A38: Attack | C38: 45 | D38: 10+ | E38: 70 | F38: 10+ | G38: 85 | H38: 24 | I38: Volt Switch | J38: 24 | K38: Volt Switch | L38: 24 | M38: Volt Switch | N38: TM32: Dazzling Gleam
A39: Defence | C39: 55 | E39: 75 | G39: 95 | H39: 27 | I39: Leaf Blade | J39: 27 | K39: Leaf Blade | L39: 27 | M39: Leaf Blade | N39: TM21: Aurora Beam
A40: SpAtk | B40: 17+ | C40: 62 | D40: 12+ | E40: 72 | F40: 17+ | G40: 92 | H40: 32 | I40: Gastro Acid | J40: 32 | K40: Gastro Acid | L40: 32 | M40: Gastro Acid | N40: TM35: Flamethrower
A41: SpDef | C41: 55 | E41: 75 | G41: 95 | H41: 36 | I41: Zing Zap | J41: 36 | K41: Zing Zap | L41: 36 | M41: Zing Zap
A42: Speed | B42: 15+ | C42: 78 | D42: 15+ | E42: 98 | F42: 10+ | G42: 123 | H42: 39 | I42: Swagger | J42: 39 | K42: Swagger | L42: 39 | M42: Swagger
A43: Total | B43: 37+ | C43: =SUM(C37:C42) -> 345 | D43: 37+ | E43: =SUM(E37:E42) -> 450 | F43: 52+ | G43: =SUM(G37:G42) -> 580 | J43: 42 | K43: Power Whip | L43: 42 | M43: Power Whip
A44: Ability 1 | B44: Adaptability | D44: Adaptability | F44: Adaptability | J44: 46 | K44: Draco Meteor | L44: 46 | M44: Draco Meteor
A45: Ability 2 | B45: - | D45: - | F45: - | J45: 50 | K45: Thunderbolt | L45: 50 | M45: Thunderbolt
A46: Ability 3 (HA) | B46: Contrary | D46: Contrary | F46: Contrary | J46: 54 | K46: Coil | L46: 54 | M46: Coil
A47: Evolution Changes | L47: 61 | M47: Leaf Storm
L48: 65 | M48: Electro Ball
...

Sheet Type Changes
B2: Typing Changes
B4: The following Pokemon have had their typing's changed to create a fresh and unique metagame for both players and enemies in Cascade White.
B5: My priority for each change was in making mechanically interesting tools to play with, with less (but not 0) consideration for theming or flavor.
B8: Pokémon | C8: Old Typing | F8: New Typing
B9: Charmander | C9: Fire | F9: Fire | G9: Dragon
B10: Charmeleon | C10: Fire | F10: Fire | G10: Dragon
B11: Charizard | C11: Fire | D11: Flying | F11: Fire | G11: Dragon
B12: Wartortle | C12: Water | F12: Water | G12: Steel
B13: Blastoise | C13: Water | F13: Water | G13: Steel
B14: Pidgey | C14: Normal | D14: Flying | F14: Flying
B15: Pidgeotto | C15: Normal | D15: Flying | F15: Flying
B16: Pidgeot | C16: Normal | D16: Flying | F16: Flying
B17: Spearow | C17: Normal | D17: Flying | F17: Dark | G17: Flying
B18: Fearow | C18: Normal | D18: Flying | F18: Dark | G18: Flying
B19: Ekans | C19: Poison | F19: Poison | G19: Dragon
B20: Arbok | C20: Poison | F20: Poison | G20: Dragon
B21: Raichu | C21: Electric | F21: Electric | G21: Ground
B22: Vulpix | C22: Fire | F22: Fire | G22: Fairy
B23: Ninetales | C23: Fire | F23: Fire | G23: Fairy
B24: Igglybuff | C24: Normal | D24: Fairy | F24: Fairy | G24: Flying
B25: Jigglypuff | C25: Normal | D25: Fairy | F25: Fairy | G25: Flying
B26: Wigglytuff | C26: Normal | D26: Fairy | F26: Fairy | G26: Flying
B27: Oddish | C27: Grass | D27: Poison | F27: Fairy | G27: Poison
B28: Gloom | C28: Grass | D28: Poison | F28: Fairy | G28: Poison
B29: Vileplume | C29: Grass | D29: Poison | F29: Fairy | G29: Poison
B30: Bellossom | C30: Grass | F30: Fairy | G30: Grass
B31: Paras | C31: Bug | D31: Grass | F31: Bug | G31: Ghost
B32: Parasect | C32: Bug | D32: Grass | F32: Bug | G32: Ghost
B33: Venonat | C33: Bug | D33: Poison | F33: Bug | G33: Psychic
B34: Venomoth | C34: Bug | D34: Poison | F34: Bug | G34: Psychic
B35: Meowth | C35: Normal | F35: Normal | G35: Steel
B36: Persian | C36: Normal | F36: Normal | G36: Steel
B37: Psyduck | C37: Water | F37: Water | G37: Psychic
B38: Golduck | C38: Water | F38: Water | G38: Psychic
B39: Growlithe | C39: Fire | F39: Fire | G39: Normal
B40: Arcanine | C40: Fire | F40: Fire | G40: Normal
B41: Poliwhirl | C41: Water | F41: Water | G41: Fighting
B42: Politoed | C42: Water | F42: Water | G42: Normal
B43: Rapidash | C43: Fire | F43: Fire | G43: Fairy
B44: Farfetch'd | C44: Normal | D44: Flying | F44: Flying | G44: Fighting
...

Sheet Move Changes
B2: Move Changes
B4: The following moves have been adjusted to cultivate a fresh and exciting metagame for Cascade White.
B8: Trapping Moves | F8: Auto-Crit Moves | J8: Accuracy Related Moves
B10: NOW INFLICT 1/8 DAMAGE PER TURN | F10: Move | G10: Changes | J10: Move | K10: Changes
B11: Move | C11: Changes | F11: Storm Throw | G11: 40 BP > 45 BP, 100% Accurate | J11: Telekinesis | K11: Lowers Evasion, Works like Rapid Spin
B12: Horn Drill | C12: OHKO > Trapping, 90% Accuracy | F12: Frost Breath | G12: 40 BP > 45 BP, 100% Accurate | K12: 65 BP, Psychic, Special, Can't Miss, Spread
C13: 0BP > 100 BP, Normal > Rock Typing | F13: Pay Day | G13: Unique Effect > Autocrit. Steel type. Special! | J13: Defog | K13: Works like Rapid Spin, Lowers Evasion
B14: Fissure | C14: OHKO > Trapping, 80% Accuracy | F14: Octazooka | G14: 65 BP > 45 BP, Autocrit | K14: 65 BP, Flying, Special, Can't Miss, Spread
C15: 0BP > 120 BP | F15: Cross Poison | G15: 70 BP > 45 BP, Autocrit | J15: Faint Attack | K15: 60 BP > 70 BP
B16: Guillotine | C16: OHKO > Trapping, 80% Accuracy | F16: Slash | G16: 70 BP > 45 BP, Autocrit | J16: Dizzy Punch | K16: Normal > Fairy, Can't Miss
C17: 0BP > 120 BP, Normal > Steel Typing | F17: Night Slash | G17: 70 BP > 40 BP, Autocrit | J17: Dig / Bounce | K17: Never Misses
B18: Imprison & Nightmare | C18: Status > Trapping, 90% Accuracy | F18: Air Cutter | G18: 60 BP > 35 BP, Autocrit | J18: Dive | K18: Never Misses, 80 BP > 100 BP
C19: 0BP > 100 BP, Special Attack | J19: Secret Power | K19: Never Misses
B20: Fire Spin, Whirlpool, Clamp | C20: 35 BP > 100 BP | J20: Retaliate | K20: Never Misses, 70 BP > 85 BP
F21: New Drawbacks | J21: Aerial Ace | K21: 60 BP > 70 BP
J22: Magnet Bomb | K22: 60 BP > 70 BP
B23: Wrap | C23: 15 BP > 100 BP, Normal > Poison Type | F23: Move | G23: Changes | J23: Shock Wave | K23: 60 BP > 70 BP
B24: Sand Tomb | C24: 35 BP > 100 BP, Physical > Special | F24: Sheer Cold | G24: Halves the damage dealt by Special moves on the next turn. | J24: Swift | K24: 60 BP > 50 BP, +1 Priority
B25: Submission | C25: 90 BP, Now a Trapping Move | F25: Overheat | J25: Magical Leaf | K25: 60 BP > 70 BP
B26: Bind | C26: 90 BP, 100% Accuracy | F26: Leaf Storm | J26: Petal Blizzard | K26: Never Misses, 80 BP > 100 BP
B27: Curse | C27: Now also traps the target until death. | F27: Draco Meteor | J27: Water Pulse | K27: Never Misses
B28: Mean Look | C28: Also lowers Defense and Evasion -1 | F28: Hyper Beam | G28: Cannot be used two turns in a row. 160 BP | J28: X-Scissor | K28: Never Misses
B29: Block | C29: Also lowers Special Defense and Evasion -1 | F29: Giga Impact | J29: Psycho Cut | K29: Never Misses
G30: Negative Priority. Never Misses. Deals half damage if attacked before executing | J30: Fake Out | K30: Never Misses
F31: Focus Punch | J31: Vital Throw | K31: No more negative priority
J32: Counter / Mirror Coat | K32: Cannot Miss
B33: Multi-Hit Moves | J33: Sacred Sword | K33: Never Misses, Hits Ghost Types
F34: Omniboost Moves | J34: Scary Face | K34: Never Misses. +1 Priority. Also Lowers evasion -2
B35: Move | C35: Changes | J35: Vise Grip | K35: Steel Type, 90 BP, cannot miss.
B36: Gear Grind | C36: 50 BP > 65 BP | F36: Move | G36: Changes | J36: Double Team | K36: Now also boosts Speed one stage.
B37: Barrage | C37: 20 BP > 25 BP, Normal > Water | F37: Ancient Power | G37: 60 BP > 80 BP, 5PP > 10PP | J37: Acid Armor | K37: Also raises Evasion one stage.
B38: Fury Swipes | C38: 15 BP > 25 BP, Normal > Dark | F38: Ominous Wind | G38: 60 BP > 80 BP, 5PP > 10PP
B39: Double Slap | C39: 18 BP > 40 BP, Normal > Fairy, Two hit | F39: Silver Wind | G39: 60 BP > 80 BP, 5PP > 10PP
B40: Vine Whip | C40: 45 BP > 40 BP, Two hit | F40: Petal Dance | G40: 120 BP > 80 BP, 10% Omniboost, no Lock-in | J40: Misc Move Functionality Changes
B41: Arm Thrust | C41: 18 BP > 25 BP | F41: Fiery Dance | G41: 10% Omniboost
B42: Spike Cannon | C42: 25 BP, Normal > Steel Typing | F42: Charge Beam | G42: 55 BP > 80 BP, 10% Omniboost | J42: Move | K42: Changes
B43: Twineedle | C43: 25 BP > 45 BP | F43: Mega Punch | G43: 120 BP > 80 BP, 10% Omniboost | J43: Hidden Power | K43: Always 70 BP, Cannot Miss
B44: Double Kick | C44: 30 BP > 35 BP | F44: Fairy Wind | G44: 50 BP > 80 BP, 10% Omniboost | J44: Ingrain | K44: 0 BP > 70 BP, Physical, 95% Acc
B45: Double Hit | C45: 35 BP > 40 BP | K45: Applies Leech Seed
B46: Triple Kick | C46: 20 BP > 40 BP. 95% Acc. Does not ramp. | J46: Sky Uppercut | K46: SE to flying type Pokemon, 80 BP
...

Sheet New Forms
A1: Rat
B2: New Forms
B12: #19 Rattata | D12: #20 Raticate
A13: Type | B13: Normal | D13: Normal
A14: HP | B14: 15+ | C14: 45 | D14: 10+ | E14: 65
A15: Attack | B15: 10+ | C15: 66 | D15: 20+ | E15: 101
A16: Defence | B16: 15+ | C16: 50 | E16: 60
A17: SpAtk | C17: 25 | E17: 50
A18: SpDef | B18: 15+ | C18: 50 | E18: 70
A19: Speed | C19: 72 | D19: 20+ | E19: 117
A20: Total | B20: 40+ | C20: =SUM(C14:C19) -> 308 | D20: 50+ | E20: =SUM(E14:E19) -> 463
A21: Ability 1 | B21: Adaptability | D21: Adaptability
A22: Ability 2 | B22: Guts | D22: Guts
A23: Ability 3 (HA) | B23: Adaptability | D23: Adaptability
A24: Evolution Changes
H25: Rattata-Alola | J25: Raticate-Alola | N25: Now Compatible With
H26: 1 | I26: Tackle | J26: 1 | K26: Tackle | N26: TM01: Psychic Fangs
H27: 1 | I27: Tail Whip | J27: 1 | K27: Tail Whip | N27: TM40: Aerial Ace
H28: 4 | I28: Quick Attack | J28: 4 | K28: Quick Attack | N28: TM65: Shadow Claw
H29: 7 | I29: Screech | J29: 7 | K29: Screech | N29: TM87: Rock Climb
H30: 10 | I30: Bite | J30: 10 | K30: Bite | N30: TM45: Lunge
B31: #19 Rattata-Alola | D31: #20 Raticate-Alola | H31: 12 | I31: Flame Wheel | J31: 12 | K31: Flame Wheel
A32: Type | B32: Normal | C32: Dark | D32: Normal | E32: Dark | H32: 13 | I32: Hyper Fang | J32: 13 | K32: Hyper Fang
A33: HP | B33: 25+ | C33: 55 | E33: 75 | H33: 16 | I33: Nuzzle | J33: 16 | K33: Nuzzle
A34: Attack | C34: 56 | D34: 10+ | E34: 81 | H34: 19 | I34: Sucker Punch | J34: 19 | K34: Sucker Punch
A35: Defence | B35: 55+ | C35: 90 | D35: 40+ | E35: 110 | H35: 23 | I35: Fire Fang | J35: 23 | K35: Fire Fang
A36: SpAtk | C36: 25 | E36: 40 | H36: 23 | I36: Ice Fang | J36: 23 | K36: Ice Fang
A37: SpDef | C37: 35 | E37: 80 | H37: 23 | I37: Thunder Fang | J37: 23 | K37: Thunder Fang
A38: Speed | B38: 20- | C38: 52 | E38: 77 | H38: 28 | I38: Crunch | J38: 28 | K38: Crunch
A39: Total | B39: 60+ | C39: =SUM(C33:C38) -> 313 | D39: 50+ | E39: =SUM(E33:E38) -> 463 | H39: 34 | I39: U-Turn | J39: 34 | K39: U-Turn
A40: Ability 1 | B40: Thick Fat | D40: Thick Fat | H40: 39 | I40: Double-Edge | J40: 39 | K40: Double-Edge
A41: Ability 2 | B41: Hustle | D41: Hustle | H41: 44 | I41: Flail | J41: 44 | K41: Flail
A42: Ability 3 (HA) | B42: Strong Jaw | D42: Strong Jaw | H42: 54 | I42: Facade | J42: 54 | K42: Facade
A43: Evolution Changes | J43: 60 | K43: Skull Bash
J44: 70 | K44: Giga Impact
B56: #26 Raichu
A57: Type | B57: Electric | C57: Ground
A58: HP | C58: 60
A59: Attack | B59: 10+ | C59: 100
A60: Defence | C60: 55
...

Sheet Theoretical Imports
B2: New Forms
H7: Chesnaught | N7: Now Compatible With
H8: 1
H9: 1
H10: 4
H11: 7
H12: 10
B13: #654 Chesnaught | H13: 12
A14: Type | B14: Grass | C14: Fighting | H14: 13
A15: HP | C15: 88 | H15: 16
A16: Attack | C16: 107 | H16: 19
A17: Defence | C17: 122 | H17: 23
A18: SpAtk | C18: 74 | H18: 23
A19: SpDef | C19: 75 | H19: 23
A20: Speed | C20: 64 | H20: 28
A21: Total | C21: =SUM(C15:C20) -> 530 | H21: 34
A22: Ability 1 | B22: Overgrow | H22: 39
A23: Ability 2 | B23: Iron Barbs | H23: 44
A24: Ability 3 (HA) | B24: Bulletproof | H24: 54
A25: Evolution Changes
H29: Delphox | N29: Now Compatible With
H30: 1
H31: 1
H32: 4
H33: 7
H34: 10
B35: #655 Delphox | H35: 12
A36: Type | B36: Fire | C36: Psychic | H36: 13
A37: HP | C37: 75 | H37: 16
A38: Attack | C38: 69 | H38: 19
A39: Defence | C39: 72 | H39: 23
A40: SpAtk | C40: 114 | H40: 23
A41: SpDef | C41: 100 | H41: 23
A42: Speed | C42: 104 | H42: 28
A43: Total | C43: =SUM(C37:C42) -> 534 | H43: 34
A44: Ability 1 | B44: Blaze | H44: 39
A45: Ability 2 | B45: Forewarn | H45: 44
A46: Ability 3 (HA) | B46: Magic Guard | H46: 54
A47: Evolution Changes
H52: Greninja | N52: Now Compatible With
...

Sheet Ability Changes
B2: Ability Tweaks
B4: Minor Functionality Changes | F4: Rivalry | J4: Infiltrator
B6: Shed Skin | C6: 100% chance to proc at the end of the turn | F6: New Effect | G6: New Users | J6: New Effect | K6: New Users
B7: Healer / Plus / Minus | C7: Protects pokemon from ally attacks, like Telepathy | F7: Increases damage dealt to and reduces damage taken from Pokemon that share a type with the user by 33%. | J7: Super effective moves are boosted by 20% and bypass barriers.
B8: Friend Guard / Forewarn
B9: Toxic Boost | C9: Halves damage from Poison status + attacks
B10: Heatproof | C10: No burns. Reduces Fire dmg taken by 75%
B11: Mold Breaker / Turboblaze / Teravolt | C11: Now also increases damage dealt by 1.1x.
F12: Pickup | J12: Healer
B13: Marvel Scale / Guts | C13: Prevents user from losing turn to paralysis.
B14: Iron Fist | C14: Now boosts Punch moves by 1.3x | F14: New Effect | G14: New Users | J14: New Effect | K14: New Users
B15: Rattled | C15: Now boosts Speed by 3 Stages | F15: Pokemon with this ability recover any items used in battle upon switching out! | J15: This Pokemon and its allies heal 1/16 of their maximum health at the end of each turn.
B16: Trace | C16: In multi-battles copies the ability of your ally.
B17: Filter / Solid Rock | C17: Reduces effectiveness mult from 2x to 1.5x
B18: Truant | C18: Prevents the user from using damaging moves on consecutive turns.
B20: Normalize | C20: The user's moves become Normal type, have neutral effectiveness, and are boosted by 20% | F20: Soundproof > Amplifier | J20: Run Away
B22: Scrappy | C22: Now also prevents Attack from being lowered | F22: New Description | G22: New Users | J22: New Effect | K22: New Users
B23: Unaware | C23: Ignores the user's stat stages as well. | F23: Boosts Sound moves by 20%, and provides immunity to Sound moves! | J23: Cannot be trapped. When reduced below 50% health, automatically switch out of battle.
B24: Flare Boost | C24: Halves damage from Burns
B25: Justified | C25: Also halves damage taken from Dark moves.
B26: Bad Dreams | C26: Traps sleeping targets in battle.
B27: Torrent / Blaze / Overgrow / Swarm | C27: Boosts respective type by 25%. Bonus doubled while below 1/3 health.
F28: Forewarn | J28: Pickpocket
B29: Unnerve | C29: Prevents the ACTIVATION of foe items.
F30: New Effect | G30: New Users | J30: New Effect | K30: New Users
B31: Weather Ability Changes | F31: Reduces damage the Pokemon and its allies take from critical hits by 25%! | J31: Steals target's item on hit with a contact move. If already holding an item, knocks it off instead.
B33: Rain Dish | C33: Heals 1/8 per turn in rain. Prevents burns
B34: Ice Body | C34: Heals 1/16 per turn outside hail, 1/8 in hail
B35: Solar Power / Chlorophyll / Flower Gift | C35: Deals 1/16 self damage per turn in sun
C36: Allows the use of full powered Solarbeam/Growth/Synth in any weather | F36: Inner Focus | J36: Hyper Cutter
B38: Slush Rush | C38: 1/2 damage from Ice moves. Can't be frozen. | F38: New Effect | G38: New Users | J38: New Effect | K38: New Users
B39: Sand Rush | C39: Halves damage taken from Rock moves. | F39: Prevents flinches, and allows Psychic moves to damage Dark-types | J39: Slicing, cutting, and claw moves are boosted by 30%. Cannot have attack dropped.
B40: Sand Force | C40: Increases damage of Rock/Ground/Steel moves by 1.2x. In sand, boost is 1.4x.
B42: Swift Swim | C42: Halves damage taken from Water moves.
B43: Cloud Nine | C43: Raises accuracy for moves when active by 1.2x
F44: Light Metal | J44: Heavy Metal
B45: Ability Nerfs
F46: New Effect | G46: New Users | J46: New Effect | K46: New Users
B47: Dry Skin | C47: Increases Fire Damage taken by 100% | F47: Boosts Speed by 50%. Reduces Defense by 33%. | J47: Boosts Defense by 50%. Reduces Speed by 33%.
B48: Regenerator | C48: Heals 20% on switch out. (down from 33%)
...

Sheet Item Changes
B2: Item Changes
F3: Added Items
B4: These are a collection of other small mechanics that have been adjusted for a more dynamic and interesting gameplay experience.
F5: Item | G5: Effect
F6: Roseli Berry | G6: Standard Effect
F7: Fairy Gem | G7: 1.5x Fairy Damage, Single Use
F8: Fairy Dust | G8: 1.2x Fairy Damage boost
B9: Item Tweaks | F9: Assault Vest | G9: 1.5x Special Defense, can't use Status moves
F10: Weakness Policy | G10: Boosts Atk and SpA by 2 when hit by SE move
B11: Item | C11: Effect | F11: Safety Goggles | G11: Prevents weather damage, blocks powders
B12: Zoom Lens | C12: Provides 1.3x Accuracy Buff | G12: Prevents accuracy from being reduced.
B13: Wide Lens | C13: Provides 1.15x Accuracy Buff | F13: Blunder Policy | G13: Boosts Speed by +2 if holders move fails
B14: Big Root | C14: Provides 50% healing increase | G14: Triggers with misses, immunities, protect, etc.
B15: Shell Bell | C15: Provides 25% Healing | F15: Throat Spray | G15: Raises SpA by 1 after using a sound move
B16: Stick | C16: Doubles Farfetch'd Physical Damage | F16: Kee Berry | G16: Boosts Defense by 2 when hit by physical
B17: Light Ball | C17: Also Doubles Eevee's Atk and SpA | F17: Maranga Berry | G17: Boots Sp. Def by 2 when hit by special
B18: MIcle Berry | C18: Triggers instantly. Provides +50% accuracy. | F18: Covert Cloak | G18: Blocks additional affects of moves
B19: Jaboca / Rowap Berry | C19: Deals 25% maximum health, up from 12.5% | F19: Clear Amulet | G19: Prevents stat drops
B20: Pinch +Stat Berries | C20: Activates at 50% health | F20: Berry Juice | G20: Now counts as a Berry for Incinerate / Pluck
B21: Custap Berry | C21: Activates at 50% health
B22: Brightpowder | C22: Buffed to a 20% chance to avoid moves | F22: Eject Pack | G22: Switch out when stats are lowered.
B23: Resist Berries | C23: No longer SEEN by the AI | F23: New Items
B24: Enigma Berry | C24: Heals 50%, up from 25% | F24: Ability Drill | G24: Boots Sp. Def by 1 when hit by special
B25: Casteliacone | C25: An 100 HP Berry Juice! | F25: Trickster Herb* | G25: Consumable, +1 Priority for a Status Move
B26: Figy Berry | C26: Heals 33% health when brought to 50%. ALWAYS CONFUSES. | F26: Attack Insurance* | G26: Deals 1/8 of a target's maximum health when
G27: the holder's attack fails to affect them.
B28: Focus Band | C28: Gives a 50% chance to reduce damage from an incoming attack by 50%. | F28: Mascot Badge | G28: Doubles Offenses, Defenses, and Speed
G29: For 1st Stage Pokemon.
B32: AI Exclusive Items
B34: The following items are limited to the AI for balance purposes. These items are designed to facilitate mechanics that make the game more challenging and interesting and are not intended for player use as a result.
F36: Colress Devices
F38: These are powerful items mostly exclusive to Team Plasma and are the result of Colress's effort to enhance Pokémon with technology.
B40: Terastalization Items | F40: Item | G40: Effect
F41: Mysterious Device | G41: +1 Atk, +1 SpA, and -1 Accuracy on switch in
B42: These items share the base functions of their non-tera counterparts. | F42: Prototype Booster | G42: +1 Atk, +1 SpA, and -1 Accuracy on switch in
B43: The "terastalization" triggers at the start of the Pokémon's first turn in battle after switching in, changing their typing into their "Tera Type" | F43: Prototype Accelerator | G43: +2 Speed, -1 Accuracy on switch in
F44: Prototype Armor | G44: +1 Def, +1 SpD, and -1 Accuracy on switch in
B45: Their Tera Type is the type of the first move in their moveset. | F45: CLRS Booster | G45: +1 Atk and +1 SpA on switch in
B46: While Terastallized, Pokémon receive STAB on moves matching their Tera Type, in addition to moves matching their original types | F46: CLRS Accelerator | G46: +2 Speed on switch in
F47: CLRS Armor | G47: +1 Def and +1 SpD on switch in
...

Sheet AI Exclusive Abilities
B2: AI Exclusive Abilities
B4: The following Pokemon have abilities that can only be accessed by the AI. This is for balance purposes, and also because many of these abilities aren't very useful or consistent in the player's hands.
B5: My priority for each change was in making mechanically interesting tools to play with, with less (but not 0) consideration for theming or flavor.
C7: Pokémon | D7: Abil 1 | G7: Abil 2 | J7: Abil 3 (HA) | M7: Abil 4 (AI Only) | P7: Abil 5 (AI Only) | S7: Abil 6 (AI Only)
B8: 1 | C8: Bulbasaur | D8: Resilient | G8: Overgrow | J8: Thick Fat | M8: Drought | P8: Chlorophyll | S8: Flower Gift
B9: 2 | C9: Ivysaur | D9: Resilient | G9: Overgrow | J9: Thick Fat | M9: Drought | P9: Chlorophyll | S9: Flower Gift
B10: 3 | C10: Venusaur | D10: Resilient | G10: Overgrow | J10: Thick Fat | M10: Drought | P10: Chlorophyll | S10: Flower Gift
B11: 4 | C11: Charmander | D11: ='Kanto - Old'!B47 -> #REF! | G11: Blaze | J11: Tough Claws | M11: Drought | P11: Intimidate | S11: Turboblaze
B12: 5 | C12: Charmeleon | D12: ='Kanto - Old'!D47 -> #REF! | G12: Blaze | J12: Tough Claws | M12: Drought | P12: Intimidate | S12: Turboblaze
B13: 6 | C13: Charizard | D13: ='Kanto - Old'!F47 -> #REF! | G13: Blaze | J13: Tough Claws | M13: Drought | P13: Intimidate | S13: Turboblaze
B14: 7 | C14: Squirtle | D14: ='Kanto - Old'!B72 -> #REF! | G14: Torrent | J14: ='Kanto - Old'!B74 -> #REF! | M14: Drizzle | P14: Quick Draw | S14: Ballistics
B15: 8 | C15: Wartortle | D15: ='Kanto - Old'!D72 -> #REF! | G15: Torrent | J15: ='Kanto - Old'!D74 -> #REF! | M15: Drizzle | P15: Quick Draw | S15: Ballistics
B16: 9 | C16: Blastoise | D16: ='Kanto - Old'!F72 -> #REF! | G16: Torrent | J16: Determined | M16: Drizzle | P16: Quick Draw | S16: Ballistics
B17: 10 | C17: Caterpie | D17: Resilient | G17: Keen Senses | J17: Swarm | M17: Anticipation | P17: Serene Grace | S17: Filter
B18: 11 | C18: Metapod | D18: Resilient | G18: ='Kanto - Old'!D100 -> #REF! | J18: Swarm | M18: Anticipation | P18: Serene Grace | S18: Filter
B19: 12 | C19: Butterfree | D19: Keen Senses | G19: Tenacity | J19: Swarm | M19: Anticipation | P19: Serene Grace | S19: Filter
B20: 13 | C20: Weedle | D20: Resilient | G20: ='Kanto - Old'!B123 -> #REF! | J20: Swarm | M20: Sniper | P20: Anticipation | S20: Stakeout
B21: 14 | C21: Kakuna | D21: Resilient | G21: ='Kanto - Old'!D123 -> #REF! | J21: Swarm | M21: Sniper | P21: Anticipation | S21: Stakeout
B22: 15 | C22: Beedrill | D22: ='Kanto - Old'!F122 -> #REF! | G22: ='Kanto - Old'!F123 -> #REF! | J22: Swarm | M22: Sniper | P22: Anticipation | S22: Stakeout
B23: 16 | C23: Pidgey | D23: ='Kanto - Old'!B143 -> #REF! | G23: ='Kanto - Old'!B144 -> #REF! | J23: ='Kanto - Old'!B145 -> #REF! | M23: Serene Grace
B24: 17 | C24: Pidgeotto | D24: ='Kanto - Old'!D143 -> #REF! | G24: ='Kanto - Old'!D144 -> #REF! | J24: ='Kanto - Old'!D145 -> #REF! | M24: Serene Grace
B25: 18 | C25: Pidgeot | D25: ='Kanto - Old'!F143 -> #REF! | G25: ='Kanto - Old'!F144 -> #REF! | J25: ='Kanto - Old'!F145 -> #REF! | M25: Serene Grace
B26: 19 | C26: Rattata | D26: Adaptability | G26: Guts
B27: 20 | C27: Raticate | D27: Adaptability | G27: Guts
B28: 21 | C28: Spearow | D28: Intimidate | G28: Defiant | M28: Sniper
B29: 22 | C29: Fearow | D29: Intimidate | G29: Hustle | M29: Sniper
B30: 23 | C30: Ekans | D30: Intimidate | G30: Sheer Force | J30: Regenerator | M30: Stakeout | P30: Arena Trap | S30: Stench
B31: 24 | C31: Arbok | D31: Intimidate | G31: Sheer Force | J31: Regenerator | M31: Stakeout | P31: Arena Trap | S31: Stench
B32: 172 | C32: Pichu | D32: Thunder Armor | G32: Static | J32: Galvanize | M32: Plus | P32: Minus
B33: 25 | C33: Pikachu | D33: Thunder Armor | G33: Static | J33: Galvanize | M33: Plus | P33: Minus
B34: 26 | C34: Raichu | D34: Teravolt | G34: Sheer Force | J34: Galvanize | M34: Plus | P34: Minus
B35: 27 | C35: Sandshrew | D35: Rough Skin | G35: Sand Force | M35: Sand Stream | P35: Sand Veil
B36: 28 | C36: Sandslash | D36: Rough Skin | G36: Sand Force | M36: Sand Stream | P36: Sand Veil
B37: 29 | C37: Nidoran-F | D37: Rivalry | G37: Sheer Force | J37: Thick Fat | M37: Sand Stream | P37: Sand Veil | S37: Anger Point
B38: 30 | C38: Nidorina | D38: Rivalry | G38: Sheer Force | J38: Thick Fat | M38: Sand Stream | P38: Sand Veil | S38: Anger Point
B39: 31 | C39: Nidoqueen | D39: Battle Armor | G39: Sheer Force | J39: Thick Fat | M39: Sand Stream | P39: Sand Veil | S39: Anger Point
B40: 32 | C40: Nidoran-M | D40: Rivalry | G40: Sheer Force | J40: Exploit | M40: Sand Stream | P40: Sand Veil | S40: Anger Point
B41: 33 | C41: Nidorino | D41: Rivalry | G41: Sheer Force | J41: Exploit | M41: Sand Stream | P41: Sand Veil | S41: Anger Point
B42: 34 | C42: Nidoking | D42: Sturdy | G42: Sheer Force | J42: Exploit | M42: Sand Stream | P42: Sand Veil | S42: Anger Point
B43: 173 | C43: Cleffa | D43: Magic Guard | G43: Unaware | J43: Friend Guard | M43: Simple
...

Sheet Notated Abilities
B2: Unova: #494-649
C7: Forewarn | F7: Blaze | I7: Chlorophyll | L7: Pickpocket
C9: Swift Swim | F9: Overgrow | I9: Swift Swim | L9: Normalize
C11: Hyper Cutter | F11: Torrent | I11: Solar Power | L11: Filter
A13: Type | C13: Pickup | I13: Cloud Nine | L13: Corrosion
A14: HP | F14: Storm Drain
A15: Attack | C15: Rivalry | I15: Rain Dish | L15: Unaware
A16: Defence | F16: Swarm
A17: SpAtk | C17: Shed Skin | I17: Ice Body | L17: Scrappy
A18: SpDef
A19: Speed | C19: Justified | I19: Sand Rush | L19: Overcoat
A20: Total
A21: Ability 1 | C21: Berserk | I21: Slush Rush | L21: Solid Rock
A22: Ability 2
A23: Ability 3 (HA) | I23: Run Away | L23: Mold Breaker
A24: Evolution Changes
I25: Unnerve | L25: Heavy Metal
C27: Thunder Armor | L27: Shed Skin
I28: Sand Force
C29: Amplifier | L29: Anger Point
I30: Thick Fat
C31: Colossal | L31: Justified
C33: Merciless | G33: Inner Focus | L33: Forewarn
A34: Type | I34: Unnerve
A35: HP | C35: Ballistics | L35: Rattled
A36: Attack | F36: Fur Coat
A37: Defence | I37: Teravolt | L37: Light Metal
A38: SpAtk | F38: Fluffy
A39: SpDef | I39: Strong Body (Clear Body) | L39: Healer
A40: Speed
A41: Total | L41: Infiltrator
A42: Ability 1 | I42: Overcoat
A43: Ability 2 | L43: Toxic Boost
A44: Ability 3 (HA) | I44: Flower Gift
A45: Evolution Changes | F45: Turboblaze
C49: Move ID | D49: Move Name | F49: Grass
D50: ----- | F50: Water
C51: 1 | D51: Concuss | F51: Dark
C52: 2 | D52: Karate Chop | F52: Flying
C53: 3 | D53: DoubleSlap | F53: Normal | I53: Normal | J53: Electric | K53: Psychic
...

Sheet Redesign Ideas
B2: New WIP Ideas
H7: Delibird
H8: 1 | I8: Ice Shard
H9: 1 | I9: Quick Attack
H10: 4 | I10: Healing Wish
H11: 11 | I11: Roost
H12: 15 | I12: Freeze Dry
B13: #225 Delibird | D13: #225 Delibird | H13: 17 | I13: Rapid Spin
A14: Type | B14: Ice | C14: Fairy | D14: Ice | E14: Fairy | H14: 20 | I14: Fling
A15: HP | B15: 10+ | C15: 55 | D15: 30+ | E15: 75 | H15: 23 | I15: Heart Stamp
A16: Attack | B16: 40+ | C16: 95 | D16: 45+ | E16: 100 | H16: 26 | I16: Present
A17: Defence | B17: 25+ | C17: 70 | D17: 25+ | E17: 70 | H17: 28 | I17: Helping Hand
A18: SpAtk | B18: 25+ | C18: 90 | D18: 30+ | E18: 95 | H18: 32 | I18: Sky Drop
A19: SpDef | B19: 25+ | C19: 70 | D19: 25+ | E19: 70 | H19: 36 | I19: Slam
A20: Speed | B20: 40+ | C20: 115 | D20: 20+ | E20: 95 | H20: 40 | I20: Play Rough
A21: Total | B21: 165+ | C21: =SUM(C15:C20) -> 495 | D21: 165+ | E21: =SUM(E15:E20) -> 505 | H21: 42 | I21: Fake Out
A22: Ability 1 | B22: Pickup | D22: Pickup | H22: 46 | I22: Tailwind
A23: Ability 2 | B23: Refrigerate | D23: Unburden | H23: 49 | I23: Flail
A24: Ability 3 (HA) | B24: Permafrost | D24: Permafrost | H24: 54 | I24: Last Resort
A25: Evolution Changes | H25: 58 | I25: Triple Axel
H29: Bonsly | J29: Sudowoodo | N29: Now Compatible With
H30: 1 | I30: Bullet Seed | J30: 1 | K30: Obstruct | N30: HM01: Cut
H31: 1 | I31: Tickle | J31: 1 | K31: Substitute | N31: TM47: Low Sweep
H32: 6 | I32: Accelerock | J32: 6 | K32: Accelerock
H33: 9 | I33: Copycat | J33: 9 | K33: Copycat
H34: 12 | I34: Covet | J34: 12 | K34: Covet
B35: #438 Bonsly | D35: #185 Sudowoodo | H35: 15 | I35: Rock Tomb | J35: 15 | K35: Rock Tomb
A36: Type | B36: Rock | D36: Rock | E36: Fairy | H36: 18 | I36: Defense Curl | J36: 18 | K36: Defense Curl
A37: HP | B37: 10+ | C37: 60 | D37: 10+ | E37: 80 | H37: 20 | I37: Nature Power | J37: 20 | K37: Nature Power
A38: Attack | B38: 5+ | C38: 85 | D38: 5+ | E38: 105 | H38: 22 | I38: Rollout | J38: 22 | K38: Rollout
A39: Defence | B39: 5+ | C39: 100 | D39: 5+ | E39: 120 | H39: 26 | I39: Dizzy Punch | J39: 26 | K39: Dizzy Punch
A40: SpAtk | C40: 10 | E40: 30 | H40: 30 | I40: Thunder Wave | J40: 30 | K40: Thunder Wave
A41: SpDef | B41: 20+ | C41: 75 | D41: 20+ | E41: 85 | H41: 33 | I41: Block | J41: 33 | K41: Block
A42: Speed | B42: 40+ | C42: 50 | D42: 40+ | E42: 70 | H42: 36 | I42: Wood Hammer | J42: 36 | K42: Wood Hammer
A43: Total | B43: 80+ | C43: =SUM(C37:C42) -> 380 | D43: 80+ | E43: =SUM(E37:E42) -> 490 | H43: 40 | I43: Rock Climb | J43: 40 | K43: Rock Climb
A44: Ability 1 | B44: Solid Rock | D44: Rock Head | H44: 43 | I44: Hammer Arm | J44: 43 | K44: Hammer Arm
A45: Ability 2 | B45: Prankster | D45: Prankster | H45: 45 | I45: Play Rough | J45: 45 | K45: Play Rough
A46: Ability 3 (HA) | B46: Rattled | D46: Rattled | H46: 48 | I46: Parting Shot | J46: 48 | K46: Parting Shot
A47: Evolution Changes | D47: Level 26 | H47: 52 | I47: Head Smash | J47: 52 | K47: Head Smash
H48: 55 | I48: Spirit Break | J48: 55 | K48: Spirit Break
...

Sheet Mechanic Changes
B2: Mechanic Changes | F2: IMPORTANT
F3: It has not yet been decided whether these changes will be implemented in Cascade White as of yet.
B4: There are very few changes to the core battle mechanics of Pokemon in this romhack, with a few notable exceptions.
F7: I am just using this page to test out formatting for such things and put some ideas down.
B8: Type Chart
B10: A few small small changes have been made to the type chart to provide a more fresh experience for players and address some small balance concerns involved with the introduction of fairies.
B12: CHANGE #1
B13: Normal | C13: The purpose of this change is to provide a small nerf to fairies and a small buff to normal types by providing them a useful and important resistance.
B14: RESISTS
B15: Fairy
C16: The flavor reasoning is that Normal represents the mundane, the ordinary, the opposite of the whimsy and magic of the fairy type.
B19: CHANGE #2
B20: Ice | C20: This is a change meant to provide a meaningful buff to ice types by providing them a useful defensive resistance with which to switch in on.
B21: RESISTS
B22: Water
C23: The flavor reasoning is that Water and Ice are simply different states of the same matter, the only difference being temperature. It should be as hard to freeze water with Ice as it is to melt Ice with water.
B28: Special Battles
F29: Mechanic Changes
B30: While exploring Unova, you will encounter battles where unique conditions are applied to make things more interesting.
B32: These encounters are rare, but become more common as you get deeper into the game. All instances are of altered battle conditions are documented in the Master Sheet.
B34: Some effects include...
B35: Perma Trick Room | C35: Trick Room is set at the start of the battle, and has an infinite duration. It can still be reset by using Trick Room yourself.
B36: Inverse Battles | C36: The type chart is inverted, turning all weaknesses into resists and resists into weaknesses.
B37: Pre-Set Hazards | C37: Hazards are set on the player's side when the battle starts, damaging Pokemon on switch in.
B38: Adjusted Type Charts | C38: Small tweaks to the type chart may be included as part of the challenge of certain areas. I.e. In Drayden's gym, Fairies resist (are not immune to) Dragon moves.
B39: Perma Status | C39: A status condition is applied to all Pokemon in battle, such as Taunt, Grudge, Torment or Heal Block.
